package com.hoopawolf.worldgen;

import com.hoopawolf.swordstone.BlockManager;
import net.minecraft.block.Block;
import net.minecraft.init.Blocks;
import net.minecraft.world.World;
import net.minecraft.world.gen.feature.WorldGenerator;

import java.util.Random;

public class VulcansRevengeWorldGen extends WorldGenerator {
    protected Block[] GetValidSpawnBlocks() {
        return new Block[]{Blocks.stone, Blocks.grass, Blocks.dirt};
    }

    public boolean LocationIsValidSpawn(World world, int i, int j, int k) {
        int distanceToAir = 0;
        Block checkID = world.getBlock(i, j, k);

        while (checkID != Blocks.air) {
            distanceToAir++;
            checkID = world.getBlock(i, j + distanceToAir, k);
        }

        if (distanceToAir > 0) {
            return false;
        }
        j += distanceToAir - 1;

        Block blockID = world.getBlock(i, j, k);
        Block blockIDAbove = world.getBlock(i, j + 1, k);
        Block blockIDBelow = world.getBlock(i, j - 1, k);
        for (Block x : GetValidSpawnBlocks()) {
            if (blockIDAbove != Blocks.air) {
                return false;
            }
            if (blockID == x) {
                return true;
            } else if (blockID == Blocks.snow && blockIDBelow == x) {
                return true;
            }
        }
        return false;
    }

    public VulcansRevengeWorldGen() {
    }

    public boolean generate(World world, Random rand, int i, int j, int k) {
        // check that each corner is one of the valid spawn blocks
        if (!LocationIsValidSpawn(world, i, j, k) || !LocationIsValidSpawn(world, i + 16, j, k) || !LocationIsValidSpawn(world, i + 16, j, k + 16) || !LocationIsValidSpawn(world, i, j, k + 16)) {
            return false;
        }

        System.out.println(i + ", " + j + ", " + k);
        world.setBlock(i + 1, j + 0, k + 7, Blocks.stone_brick_stairs);
        world.setBlock(i + 1, j + 0, k + 8, Blocks.stone_brick_stairs);
        world.setBlock(i + 1, j + 0, k + 9, Blocks.stone_brick_stairs);
        world.setBlock(i + 1, j + 0, k + 10, Blocks.stone_brick_stairs);
        world.setBlock(i + 1, j + 0, k + 11, Blocks.stone_brick_stairs);
        world.setBlock(i + 1, j + 0, k + 12, Blocks.stone_brick_stairs);
        world.setBlock(i + 1, j + 0, k + 13, Blocks.stone_brick_stairs);
        world.setBlock(i + 1, j + 3, k + 7, Blocks.leaves, 3, 1);
        world.setBlock(i + 1, j + 3, k + 8, Blocks.leaves, 3, 1);
        world.setBlock(i + 1, j + 3, k + 9, Blocks.leaves, 3, 1);
        world.setBlock(i + 1, j + 3, k + 10, Blocks.leaves, 3, 1);
        world.setBlock(i + 1, j + 4, k + 8, Blocks.leaves, 3, 1);
        world.setBlock(i + 1, j + 4, k + 9, Blocks.leaves, 3, 1);
        world.setBlock(i + 1, j + 4, k + 10, Blocks.leaves, 3, 1);
        world.setBlock(i + 1, j + 4, k + 11, Blocks.leaves, 3, 1);
        world.setBlock(i + 1, j + 6, k + 12, Blocks.leaves, 3, 1);
        world.setBlock(i + 1, j + 6, k + 13, Blocks.leaves, 3, 1);
        world.setBlock(i + 1, j + 6, k + 14, Blocks.leaves, 3, 1);
        world.setBlock(i + 1, j + 6, k + 15, Blocks.leaves, 3, 1);
        world.setBlock(i + 1, j + 6, k + 16, Blocks.leaves, 3, 1);
        world.setBlock(i + 1, j + 7, k + 13, Blocks.leaves, 3, 1);
        world.setBlock(i + 1, j + 7, k + 14, Blocks.leaves, 3, 1);
        world.setBlock(i + 1, j + 7, k + 15, Blocks.leaves, 3, 1);
        world.setBlock(i + 1, j + 7, k + 16, Blocks.leaves, 3, 1);
        world.setBlock(i + 2, j + 0, k + 3, Blocks.stone_brick_stairs, 2, 1);
        world.setBlock(i + 2, j + 0, k + 4, Blocks.stone_brick_stairs);
        world.setBlock(i + 2, j + 0, k + 5, Blocks.stone_brick_stairs);
        world.setBlock(i + 2, j + 0, k + 6, Blocks.stone_brick_stairs);
        world.setBlock(i + 2, j + 0, k + 7, Blocks.stone_brick_stairs, 2, 1);
        world.setBlock(i + 2, j + 0, k + 8, Blocks.stonebrick);
        world.setBlock(i + 2, j + 0, k + 9, Blocks.stonebrick);
        world.setBlock(i + 2, j + 0, k + 10, Blocks.stonebrick);
        world.setBlock(i + 2, j + 0, k + 11, Blocks.stonebrick);
        world.setBlock(i + 2, j + 0, k + 12, Blocks.stonebrick);
        world.setBlock(i + 2, j + 0, k + 13, Blocks.stone_brick_stairs, 3, 1);
        world.setBlock(i + 2, j + 0, k + 14, Blocks.stone_brick_stairs);
        world.setBlock(i + 2, j + 0, k + 15, Blocks.stone_brick_stairs);
        world.setBlock(i + 2, j + 0, k + 16, Blocks.stone_brick_stairs);
        world.setBlock(i + 2, j + 0, k + 17, Blocks.stone_brick_stairs, 3, 1);
        world.setBlock(i + 2, j + 3, k + 7, Blocks.leaves, 3, 1);
        world.setBlock(i + 2, j + 3, k + 8, Blocks.leaves, 3, 1);
        world.setBlock(i + 2, j + 3, k + 9, Blocks.leaves, 3, 1);
        world.setBlock(i + 2, j + 3, k + 10, Blocks.leaves, 3, 1);
        world.setBlock(i + 2, j + 3, k + 11, Blocks.leaves, 3, 1);
        world.setBlock(i + 2, j + 4, k + 7, Blocks.leaves, 3, 1);
        world.setBlock(i + 2, j + 4, k + 8, Blocks.leaves, 3, 1);
        world.setBlock(i + 2, j + 4, k + 9, Blocks.leaves, 3, 1);
        world.setBlock(i + 2, j + 4, k + 10, Blocks.leaves, 3, 1);
        world.setBlock(i + 2, j + 4, k + 11, Blocks.leaves, 3, 1);
        world.setBlock(i + 2, j + 5, k + 9, Blocks.leaves, 3, 1);
        world.setBlock(i + 2, j + 5, k + 10, Blocks.leaves, 3, 1);
        world.setBlock(i + 2, j + 6, k + 9, Blocks.leaves, 3, 1);
        world.setBlock(i + 2, j + 6, k + 12, Blocks.leaves, 3, 1);
        world.setBlock(i + 2, j + 6, k + 13, Blocks.leaves, 3, 1);
        world.setBlock(i + 2, j + 6, k + 14, Blocks.leaves, 3, 1);
        world.setBlock(i + 2, j + 6, k + 15, Blocks.leaves, 3, 1);
        world.setBlock(i + 2, j + 6, k + 16, Blocks.leaves, 3, 1);
        world.setBlock(i + 2, j + 7, k + 12, Blocks.leaves, 3, 1);
        world.setBlock(i + 2, j + 7, k + 13, Blocks.leaves, 3, 1);
        world.setBlock(i + 2, j + 7, k + 14, Blocks.leaves, 3, 1);
        world.setBlock(i + 2, j + 7, k + 15, Blocks.leaves, 3, 1);
        world.setBlock(i + 2, j + 7, k + 16, Blocks.leaves, 3, 1);
        world.setBlock(i + 2, j + 8, k + 13, Blocks.leaves, 3, 1);
        world.setBlock(i + 2, j + 8, k + 14, Blocks.leaves, 3, 1);
        world.setBlock(i + 2, j + 9, k + 14, Blocks.leaves, 3, 1);
        world.setBlock(i + 3, j + 0, k + 3, Blocks.stone_brick_stairs, 2, 1);
        world.setBlock(i + 3, j + 0, k + 4, Blocks.stonebrick);
        world.setBlock(i + 3, j + 0, k + 5, Blocks.stonebrick);
        world.setBlock(i + 3, j + 0, k + 6, Blocks.stonebrick, 2, 1);
        world.setBlock(i + 3, j + 0, k + 7, Blocks.stonebrick);
        world.setBlock(i + 3, j + 0, k + 8, Blocks.stone_slab, 5, 1);
        world.setBlock(i + 3, j + 0, k + 9, Blocks.log, 3, 1);
        world.setBlock(i + 3, j + 0, k + 10, Blocks.stonebrick);
        world.setBlock(i + 3, j + 0, k + 11, Blocks.stonebrick);
        world.setBlock(i + 3, j + 0, k + 12, Blocks.stonebrick, 2, 1);
        world.setBlock(i + 3, j + 0, k + 13, Blocks.stonebrick);
        world.setBlock(i + 3, j + 0, k + 14, Blocks.log, 3, 1);
        world.setBlock(i + 3, j + 0, k + 15, Blocks.stonebrick);
        world.setBlock(i + 3, j + 0, k + 16, Blocks.stonebrick);
        world.setBlock(i + 3, j + 0, k + 17, Blocks.stone_brick_stairs, 3, 1);
        world.setBlock(i + 3, j + 1, k + 9, Blocks.log, 3, 1);
        world.setBlock(i + 3, j + 1, k + 14, Blocks.log, 3, 1);
        world.setBlock(i + 3, j + 2, k + 9, Blocks.log, 3, 1);
        world.setBlock(i + 3, j + 2, k + 14, Blocks.log, 3, 1);
        world.setBlock(i + 3, j + 3, k + 7, Blocks.leaves, 3, 1);
        world.setBlock(i + 3, j + 3, k + 8, Blocks.leaves, 3, 1);
        world.setBlock(i + 3, j + 3, k + 9, Blocks.log, 3, 1);
        world.setBlock(i + 3, j + 3, k + 10, Blocks.leaves, 3, 1);
        world.setBlock(i + 3, j + 3, k + 11, Blocks.leaves, 3, 1);
        world.setBlock(i + 3, j + 3, k + 14, Blocks.log, 3, 1);
        world.setBlock(i + 3, j + 4, k + 7, Blocks.leaves, 3, 1);
        world.setBlock(i + 3, j + 4, k + 8, Blocks.leaves, 3, 1);
        world.setBlock(i + 3, j + 4, k + 9, Blocks.log, 3, 1);
        world.setBlock(i + 3, j + 4, k + 10, Blocks.leaves, 3, 1);
        world.setBlock(i + 3, j + 4, k + 11, Blocks.leaves, 3, 1);
        world.setBlock(i + 3, j + 4, k + 14, Blocks.log, 3, 1);
        world.setBlock(i + 3, j + 5, k + 8, Blocks.leaves, 3, 1);
        world.setBlock(i + 3, j + 5, k + 9, Blocks.log, 3, 1);
        world.setBlock(i + 3, j + 5, k + 10, Blocks.leaves, 3, 1);
        world.setBlock(i + 3, j + 5, k + 14, Blocks.log, 3, 1);
        world.setBlock(i + 3, j + 6, k + 8, Blocks.leaves, 3, 1);
        world.setBlock(i + 3, j + 6, k + 9, Blocks.leaves, 3, 1);
        world.setBlock(i + 3, j + 6, k + 10, Blocks.leaves, 3, 1);
        world.setBlock(i + 3, j + 6, k + 12, Blocks.leaves, 3, 1);
        world.setBlock(i + 3, j + 6, k + 13, Blocks.leaves, 3, 1);
        world.setBlock(i + 3, j + 6, k + 14, Blocks.log, 3, 1);
        world.setBlock(i + 3, j + 6, k + 15, Blocks.leaves, 3, 1);
        world.setBlock(i + 3, j + 6, k + 16, Blocks.leaves, 3, 1);
        world.setBlock(i + 3, j + 7, k + 12, Blocks.leaves, 3, 1);
        world.setBlock(i + 3, j + 7, k + 13, Blocks.leaves, 3, 1);
        world.setBlock(i + 3, j + 7, k + 14, Blocks.log, 3, 1);
        world.setBlock(i + 3, j + 7, k + 15, Blocks.leaves, 3, 1);
        world.setBlock(i + 3, j + 7, k + 16, Blocks.leaves, 3, 1);
        world.setBlock(i + 3, j + 8, k + 13, Blocks.leaves, 3, 1);
        world.setBlock(i + 3, j + 8, k + 14, Blocks.log, 3, 1);
        world.setBlock(i + 3, j + 8, k + 15, Blocks.leaves, 3, 1);
        world.setBlock(i + 3, j + 9, k + 13, Blocks.leaves, 3, 1);
        world.setBlock(i + 3, j + 9, k + 14, Blocks.leaves, 3, 1);
        world.setBlock(i + 3, j + 9, k + 15, Blocks.leaves, 3, 1);
        world.setBlock(i + 4, j + 0, k + 2, Blocks.stone_brick_stairs, 2, 1);
        world.setBlock(i + 4, j + 0, k + 3, Blocks.stone_brick_stairs);
        world.setBlock(i + 4, j + 0, k + 4, Blocks.stonebrick);
        world.setBlock(i + 4, j + 0, k + 5, Blocks.stonebrick);
        world.setBlock(i + 4, j + 0, k + 6, Blocks.stonebrick, 1, 1);
        world.setBlock(i + 4, j + 0, k + 7, Blocks.stonebrick);
        world.setBlock(i + 4, j + 0, k + 8, Blocks.stone_slab, 5, 1);
        world.setBlock(i + 4, j + 0, k + 9, Blocks.stonebrick);
        world.setBlock(i + 4, j + 0, k + 10, Blocks.stonebrick);
        world.setBlock(i + 4, j + 0, k + 11, Blocks.stonebrick);
        world.setBlock(i + 4, j + 0, k + 12, Blocks.stonebrick);
        world.setBlock(i + 4, j + 0, k + 13, Blocks.stone_slab, 5, 1);
        world.setBlock(i + 4, j + 0, k + 14, Blocks.stonebrick);
        world.setBlock(i + 4, j + 0, k + 15, Blocks.stonebrick, 2, 1);
        world.setBlock(i + 4, j + 0, k + 16, Blocks.stonebrick);
        world.setBlock(i + 4, j + 0, k + 17, Blocks.stone_brick_stairs);
        world.setBlock(i + 4, j + 0, k + 18, Blocks.stone_brick_stairs, 3, 1);
        world.setBlock(i + 4, j + 3, k + 7, Blocks.leaves, 3, 1);
        world.setBlock(i + 4, j + 3, k + 8, Blocks.leaves, 3, 1);
        world.setBlock(i + 4, j + 3, k + 9, Blocks.leaves, 3, 1);
        world.setBlock(i + 4, j + 3, k + 10, Blocks.leaves, 3, 1);
        world.setBlock(i + 4, j + 3, k + 11, Blocks.leaves, 3, 1);
        world.setBlock(i + 4, j + 4, k + 7, Blocks.leaves, 3, 1);
        world.setBlock(i + 4, j + 4, k + 8, Blocks.leaves, 3, 1);
        world.setBlock(i + 4, j + 4, k + 9, Blocks.leaves, 3, 1);
        world.setBlock(i + 4, j + 4, k + 10, Blocks.leaves, 3, 1);
        world.setBlock(i + 4, j + 4, k + 11, Blocks.leaves, 3, 1);
        world.setBlock(i + 4, j + 5, k + 9, Blocks.leaves, 3, 1);
        world.setBlock(i + 4, j + 6, k + 9, Blocks.leaves, 3, 1);
        world.setBlock(i + 4, j + 6, k + 12, Blocks.leaves, 3, 1);
        world.setBlock(i + 4, j + 6, k + 13, Blocks.leaves, 3, 1);
        world.setBlock(i + 4, j + 6, k + 14, Blocks.leaves, 3, 1);
        world.setBlock(i + 4, j + 6, k + 15, Blocks.leaves, 3, 1);
        world.setBlock(i + 4, j + 6, k + 16, Blocks.leaves, 3, 1);
        world.setBlock(i + 4, j + 7, k + 12, Blocks.leaves, 3, 1);
        world.setBlock(i + 4, j + 7, k + 13, Blocks.leaves, 3, 1);
        world.setBlock(i + 4, j + 7, k + 14, Blocks.leaves, 3, 1);
        world.setBlock(i + 4, j + 7, k + 15, Blocks.leaves, 3, 1);
        world.setBlock(i + 4, j + 7, k + 16, Blocks.leaves, 3, 1);
        world.setBlock(i + 4, j + 8, k + 14, Blocks.leaves, 3, 1);
        world.setBlock(i + 4, j + 8, k + 15, Blocks.leaves, 3, 1);
        world.setBlock(i + 4, j + 9, k + 14, Blocks.leaves, 3, 1);
        world.setBlock(i + 5, j + 0, k + 2, Blocks.stone_brick_stairs, 2, 1);
        world.setBlock(i + 5, j + 0, k + 3, Blocks.stonebrick);
        world.setBlock(i + 5, j + 0, k + 4, Blocks.stonebrick);
        world.setBlock(i + 5, j + 0, k + 5, Blocks.stonebrick, 2, 1);
        world.setBlock(i + 5, j + 0, k + 6, Blocks.stonebrick);
        world.setBlock(i + 5, j + 0, k + 7, Blocks.stonebrick);
        world.setBlock(i + 5, j + 0, k + 8, Blocks.stone_slab, 5, 1);
        world.setBlock(i + 5, j + 0, k + 9, Blocks.stonebrick, 2, 1);
        world.setBlock(i + 5, j + 0, k + 10, Blocks.stonebrick);
        world.setBlock(i + 5, j + 0, k + 11, Blocks.stonebrick);
        world.setBlock(i + 5, j + 0, k + 12, Blocks.stonebrick, 1, 1);
        world.setBlock(i + 5, j + 0, k + 13, Blocks.stonebrick);
        world.setBlock(i + 5, j + 0, k + 14, Blocks.stonebrick);
        world.setBlock(i + 5, j + 0, k + 15, Blocks.stonebrick);
        world.setBlock(i + 5, j + 0, k + 16, Blocks.stonebrick, 1, 1);
        world.setBlock(i + 5, j + 0, k + 17, Blocks.stonebrick);
        world.setBlock(i + 5, j + 0, k + 18, Blocks.stone_brick_stairs, 3, 1);
        world.setBlock(i + 5, j + 3, k + 7, Blocks.leaves, 3, 1);
        world.setBlock(i + 5, j + 3, k + 8, Blocks.leaves, 3, 1);
        world.setBlock(i + 5, j + 3, k + 9, Blocks.leaves, 3, 1);
        world.setBlock(i + 5, j + 3, k + 10, Blocks.leaves, 3, 1);
        world.setBlock(i + 5, j + 4, k + 7, Blocks.leaves, 3, 1);
        world.setBlock(i + 5, j + 4, k + 8, Blocks.leaves, 3, 1);
        world.setBlock(i + 5, j + 4, k + 9, Blocks.leaves, 3, 1);
        world.setBlock(i + 5, j + 4, k + 10, Blocks.leaves, 3, 1);
        world.setBlock(i + 5, j + 4, k + 11, Blocks.leaves, 3, 1);
        world.setBlock(i + 5, j + 6, k + 12, Blocks.leaves, 3, 1);
        world.setBlock(i + 5, j + 6, k + 13, Blocks.leaves, 3, 1);
        world.setBlock(i + 5, j + 6, k + 14, Blocks.leaves, 3, 1);
        world.setBlock(i + 5, j + 6, k + 15, Blocks.leaves, 3, 1);
        world.setBlock(i + 5, j + 6, k + 16, Blocks.leaves, 3, 1);
        world.setBlock(i + 5, j + 7, k + 12, Blocks.leaves, 3, 1);
        world.setBlock(i + 5, j + 7, k + 13, Blocks.leaves, 3, 1);
        world.setBlock(i + 5, j + 7, k + 14, Blocks.leaves, 3, 1);
        world.setBlock(i + 5, j + 7, k + 15, Blocks.leaves, 3, 1);
        world.setBlock(i + 5, j + 7, k + 16, Blocks.leaves, 3, 1);
        world.setBlock(i + 6, j + 0, k + 2, Blocks.stone_brick_stairs, 2, 1);
        world.setBlock(i + 6, j + 0, k + 3, Blocks.stonebrick);
        world.setBlock(i + 6, j + 0, k + 4, Blocks.stonebrick);
        world.setBlock(i + 6, j + 0, k + 5, Blocks.stonebrick, 2, 1);
        world.setBlock(i + 6, j + 0, k + 6, Blocks.stonebrick, 2, 1);
        world.setBlock(i + 6, j + 0, k + 7, Blocks.stonebrick);
        world.setBlock(i + 6, j + 0, k + 8, Blocks.stonebrick, 1, 1);
        world.setBlock(i + 6, j + 0, k + 9, Blocks.stonebrick);
        world.setBlock(i + 6, j + 0, k + 10, Blocks.stonebrick);
        world.setBlock(i + 6, j + 0, k + 11, Blocks.stonebrick, 2, 1);
        world.setBlock(i + 6, j + 0, k + 12, Blocks.stonebrick);
        world.setBlock(i + 6, j + 0, k + 13, Blocks.stonebrick);
        world.setBlock(i + 6, j + 0, k + 14, Blocks.stonebrick, 2, 1);
        world.setBlock(i + 6, j + 0, k + 15, Blocks.stone_slab, 5, 1);
        world.setBlock(i + 6, j + 0, k + 16, Blocks.stonebrick);
        world.setBlock(i + 6, j + 0, k + 17, Blocks.stonebrick);
        world.setBlock(i + 6, j + 0, k + 18, Blocks.stone_brick_stairs, 3, 1);
        world.setBlock(i + 6, j + 5, k + 14, Blocks.leaves, 3, 1);
        world.setBlock(i + 6, j + 5, k + 15, Blocks.leaves, 3, 1);
        world.setBlock(i + 6, j + 5, k + 16, Blocks.leaves, 3, 1);
        world.setBlock(i + 6, j + 5, k + 17, Blocks.leaves, 3, 1);
        world.setBlock(i + 6, j + 5, k + 18, Blocks.leaves, 3, 1);
        world.setBlock(i + 6, j + 6, k + 15, Blocks.leaves, 3, 1);
        world.setBlock(i + 6, j + 6, k + 16, Blocks.leaves, 3, 1);
        world.setBlock(i + 6, j + 6, k + 17, Blocks.leaves, 3, 1);
        world.setBlock(i + 6, j + 6, k + 18, Blocks.leaves, 3, 1);
        world.setBlock(i + 7, j + 0, k + 1, Blocks.stone_brick_stairs, 2, 1);
        world.setBlock(i + 7, j + 0, k + 2, Blocks.stone_brick_stairs);
        world.setBlock(i + 7, j + 0, k + 3, Blocks.stone_slab, 5, 1);
        world.setBlock(i + 7, j + 0, k + 4, Blocks.stone_slab, 5, 1);
        world.setBlock(i + 7, j + 0, k + 5, Blocks.stonebrick, 2, 1);
        world.setBlock(i + 7, j + 0, k + 6, Blocks.stonebrick, 1, 1);
        world.setBlock(i + 7, j + 0, k + 7, Blocks.stonebrick);
        world.setBlock(i + 7, j + 0, k + 8, Blocks.stonebrick);
        world.setBlock(i + 7, j + 0, k + 9, Blocks.stonebrick);
        world.setBlock(i + 7, j + 0, k + 10, Blocks.stonebrick);
        world.setBlock(i + 7, j + 0, k + 11, Blocks.stonebrick);
        world.setBlock(i + 7, j + 0, k + 12, Blocks.stonebrick);
        world.setBlock(i + 7, j + 0, k + 13, Blocks.stonebrick);
        world.setBlock(i + 7, j + 0, k + 14, Blocks.stone_slab, 5, 1);
        world.setBlock(i + 7, j + 0, k + 15, Blocks.stone_slab, 5, 1);
        world.setBlock(i + 7, j + 0, k + 16, Blocks.stonebrick);
        world.setBlock(i + 7, j + 0, k + 17, Blocks.stonebrick, 1, 1);
        world.setBlock(i + 7, j + 0, k + 18, Blocks.stone_brick_stairs);
        world.setBlock(i + 7, j + 0, k + 19, Blocks.stone_brick_stairs, 3, 1);
        world.setBlock(i + 7, j + 4, k + 2, Blocks.leaves, 3, 1);
        world.setBlock(i + 7, j + 4, k + 3, Blocks.leaves, 3, 1);
        world.setBlock(i + 7, j + 4, k + 4, Blocks.leaves, 3, 1);
        world.setBlock(i + 7, j + 4, k + 5, Blocks.leaves, 3, 1);
        world.setBlock(i + 7, j + 4, k + 6, Blocks.leaves, 3, 1);
        world.setBlock(i + 7, j + 5, k + 3, Blocks.leaves, 3, 1);
        world.setBlock(i + 7, j + 5, k + 4, Blocks.leaves, 3, 1);
        world.setBlock(i + 7, j + 5, k + 5, Blocks.leaves, 3, 1);
        world.setBlock(i + 7, j + 5, k + 6, Blocks.leaves, 3, 1);
        world.setBlock(i + 7, j + 5, k + 14, Blocks.leaves, 3, 1);
        world.setBlock(i + 7, j + 5, k + 15, Blocks.leaves, 3, 1);
        world.setBlock(i + 7, j + 5, k + 16, Blocks.leaves, 3, 1);
        world.setBlock(i + 7, j + 5, k + 17, Blocks.leaves, 3, 1);
        world.setBlock(i + 7, j + 5, k + 18, Blocks.leaves, 3, 1);
        world.setBlock(i + 7, j + 6, k + 14, Blocks.leaves, 3, 1);
        world.setBlock(i + 7, j + 6, k + 15, Blocks.leaves, 3, 1);
        world.setBlock(i + 7, j + 6, k + 16, Blocks.leaves, 3, 1);
        world.setBlock(i + 7, j + 6, k + 17, Blocks.leaves, 3, 1);
        world.setBlock(i + 7, j + 6, k + 18, Blocks.leaves, 3, 1);
        world.setBlock(i + 7, j + 7, k + 16, Blocks.leaves, 3, 1);
        world.setBlock(i + 7, j + 7, k + 17, Blocks.leaves, 3, 1);
        world.setBlock(i + 7, j + 8, k + 16, Blocks.leaves, 3, 1);
        world.setBlock(i + 8, j + 0, k + 1, Blocks.stone_brick_stairs, 2, 1);
        world.setBlock(i + 8, j + 0, k + 2, Blocks.stonebrick);
        world.setBlock(i + 8, j + 0, k + 3, Blocks.stonebrick);
        world.setBlock(i + 8, j + 0, k + 4, Blocks.stonebrick);
        world.setBlock(i + 8, j + 0, k + 5, Blocks.stonebrick);
        world.setBlock(i + 8, j + 0, k + 6, Blocks.stone_slab, 5, 1);
        world.setBlock(i + 8, j + 0, k + 7, Blocks.stone_slab, 5, 1);
        world.setBlock(i + 8, j + 0, k + 8, Blocks.stonebrick);
        world.setBlock(i + 8, j + 0, k + 9, Blocks.stonebrick);
        world.setBlock(i + 8, j + 0, k + 10, Blocks.stonebrick);
        world.setBlock(i + 8, j + 0, k + 11, Blocks.stonebrick);
        world.setBlock(i + 8, j + 0, k + 12, Blocks.stonebrick);
        world.setBlock(i + 8, j + 0, k + 13, Blocks.stonebrick);
        world.setBlock(i + 8, j + 0, k + 14, Blocks.stonebrick, 1, 1);
        world.setBlock(i + 8, j + 0, k + 15, Blocks.stonebrick, 2, 1);
        world.setBlock(i + 8, j + 0, k + 16, Blocks.log, 3, 1);
        world.setBlock(i + 8, j + 0, k + 17, Blocks.stonebrick);
        world.setBlock(i + 8, j + 0, k + 18, Blocks.stonebrick);
        world.setBlock(i + 8, j + 0, k + 19, Blocks.stone_brick_stairs, 3, 1);
        world.setBlock(i + 8, j + 1, k + 8, Blocks.stonebrick);
        world.setBlock(i + 8, j + 1, k + 12, Blocks.stonebrick, 2, 1);
        world.setBlock(i + 8, j + 1, k + 16, Blocks.log, 3, 1);
        world.setBlock(i + 8, j + 2, k + 8, Blocks.stonebrick, 1, 1);
        world.setBlock(i + 8, j + 2, k + 12, Blocks.stonebrick);
        world.setBlock(i + 8, j + 2, k + 16, Blocks.log, 3, 1);
        world.setBlock(i + 8, j + 3, k + 8, Blocks.stonebrick, 3, 1);
        world.setBlock(i + 8, j + 3, k + 12, Blocks.stonebrick, 3, 1);
        world.setBlock(i + 8, j + 3, k + 16, Blocks.log, 3, 1);
        world.setBlock(i + 8, j + 4, k + 2, Blocks.leaves, 3, 1);
        world.setBlock(i + 8, j + 4, k + 3, Blocks.leaves, 3, 1);
        world.setBlock(i + 8, j + 4, k + 4, Blocks.leaves, 3, 1);
        world.setBlock(i + 8, j + 4, k + 5, Blocks.leaves, 3, 1);
        world.setBlock(i + 8, j + 4, k + 6, Blocks.leaves, 3, 1);
        world.setBlock(i + 8, j + 4, k + 16, Blocks.log, 3, 1);
        world.setBlock(i + 8, j + 5, k + 2, Blocks.leaves, 3, 1);
        world.setBlock(i + 8, j + 5, k + 3, Blocks.leaves, 3, 1);
        world.setBlock(i + 8, j + 5, k + 4, Blocks.leaves, 3, 1);
        world.setBlock(i + 8, j + 5, k + 5, Blocks.leaves, 3, 1);
        world.setBlock(i + 8, j + 5, k + 6, Blocks.leaves, 3, 1);
        world.setBlock(i + 8, j + 5, k + 14, Blocks.leaves, 3, 1);
        world.setBlock(i + 8, j + 5, k + 15, Blocks.leaves, 3, 1);
        world.setBlock(i + 8, j + 5, k + 16, Blocks.log, 3, 1);
        world.setBlock(i + 8, j + 5, k + 17, Blocks.leaves, 3, 1);
        world.setBlock(i + 8, j + 5, k + 18, Blocks.leaves, 3, 1);
        world.setBlock(i + 8, j + 6, k + 3, Blocks.leaves, 3, 1);
        world.setBlock(i + 8, j + 6, k + 4, Blocks.leaves, 3, 1);
        world.setBlock(i + 8, j + 6, k + 14, Blocks.leaves, 3, 1);
        world.setBlock(i + 8, j + 6, k + 15, Blocks.leaves, 3, 1);
        world.setBlock(i + 8, j + 6, k + 16, Blocks.log, 3, 1);
        world.setBlock(i + 8, j + 6, k + 17, Blocks.leaves, 3, 1);
        world.setBlock(i + 8, j + 6, k + 18, Blocks.leaves, 3, 1);
        world.setBlock(i + 8, j + 7, k + 4, Blocks.leaves, 3, 1);
        world.setBlock(i + 8, j + 7, k + 15, Blocks.leaves, 3, 1);
        world.setBlock(i + 8, j + 7, k + 16, Blocks.log, 3, 1);
        world.setBlock(i + 8, j + 7, k + 17, Blocks.leaves, 3, 1);
        world.setBlock(i + 8, j + 8, k + 15, Blocks.leaves, 3, 1);
        world.setBlock(i + 8, j + 8, k + 16, Blocks.leaves, 3, 1);
        world.setBlock(i + 8, j + 8, k + 17, Blocks.leaves, 3, 1);
        world.setBlock(i + 9, j + 0, k + 1, Blocks.stone_brick_stairs, 2, 1);
        world.setBlock(i + 9, j + 0, k + 2, Blocks.stonebrick);
        world.setBlock(i + 9, j + 0, k + 3, Blocks.stonebrick, 2, 1);
        world.setBlock(i + 9, j + 0, k + 4, Blocks.log, 3, 1);
        world.setBlock(i + 9, j + 0, k + 5, Blocks.stonebrick);
        world.setBlock(i + 9, j + 0, k + 6, Blocks.stone_slab, 5, 1);
        world.setBlock(i + 9, j + 0, k + 7, Blocks.stonebrick);
        world.setBlock(i + 9, j + 0, k + 8, Blocks.stonebrick);
        world.setBlock(i + 9, j + 0, k + 9, Blocks.stonebrick);
        world.setBlock(i + 9, j + 0, k + 10, Blocks.stonebrick);
        world.setBlock(i + 9, j + 0, k + 11, Blocks.stonebrick);
        world.setBlock(i + 9, j + 0, k + 12, Blocks.stonebrick);
        world.setBlock(i + 9, j + 0, k + 13, Blocks.stonebrick, 2, 1);
        world.setBlock(i + 9, j + 0, k + 14, Blocks.stonebrick);
        world.setBlock(i + 9, j + 0, k + 15, Blocks.stonebrick);
        world.setBlock(i + 9, j + 0, k + 16, Blocks.stonebrick);
        world.setBlock(i + 9, j + 0, k + 17, Blocks.stonebrick, 2, 1);
        world.setBlock(i + 9, j + 0, k + 18, Blocks.stonebrick);
        world.setBlock(i + 9, j + 0, k + 19, Blocks.stone_brick_stairs, 3, 1);
        world.setBlock(i + 9, j + 1, k + 4, Blocks.log, 3, 1);
        world.setBlock(i + 9, j + 1, k + 9, Blocks.stone_brick_stairs, 2, 1);
        world.setBlock(i + 9, j + 1, k + 10, Blocks.stone_brick_stairs);
        world.setBlock(i + 9, j + 1, k + 11, Blocks.stone_brick_stairs);
        world.setBlock(i + 9, j + 2, k + 4, Blocks.log, 3, 1);
        world.setBlock(i + 9, j + 3, k + 4, Blocks.log, 3, 1);
        world.setBlock(i + 9, j + 4, k + 2, Blocks.leaves, 3, 1);
        world.setBlock(i + 9, j + 4, k + 3, Blocks.leaves, 3, 1);
        world.setBlock(i + 9, j + 4, k + 4, Blocks.log, 3, 1);
        world.setBlock(i + 9, j + 4, k + 5, Blocks.leaves, 3, 1);
        world.setBlock(i + 9, j + 4, k + 6, Blocks.leaves, 3, 1);
        world.setBlock(i + 9, j + 5, k + 2, Blocks.leaves, 3, 1);
        world.setBlock(i + 9, j + 5, k + 3, Blocks.leaves, 3, 1);
        world.setBlock(i + 9, j + 5, k + 4, Blocks.log, 3, 1);
        world.setBlock(i + 9, j + 5, k + 5, Blocks.leaves, 3, 1);
        world.setBlock(i + 9, j + 5, k + 6, Blocks.leaves, 3, 1);
        world.setBlock(i + 9, j + 5, k + 14, Blocks.leaves, 3, 1);
        world.setBlock(i + 9, j + 5, k + 15, Blocks.leaves, 3, 1);
        world.setBlock(i + 9, j + 5, k + 16, Blocks.leaves, 3, 1);
        world.setBlock(i + 9, j + 5, k + 17, Blocks.leaves, 3, 1);
        world.setBlock(i + 9, j + 5, k + 18, Blocks.leaves, 3, 1);
        world.setBlock(i + 9, j + 6, k + 3, Blocks.leaves, 3, 1);
        world.setBlock(i + 9, j + 6, k + 4, Blocks.log, 3, 1);
        world.setBlock(i + 9, j + 6, k + 5, Blocks.leaves, 3, 1);
        world.setBlock(i + 9, j + 6, k + 13, Blocks.leaves, 3, 1);
        world.setBlock(i + 9, j + 6, k + 14, Blocks.leaves, 3, 1);
        world.setBlock(i + 9, j + 6, k + 15, Blocks.leaves, 3, 1);
        world.setBlock(i + 9, j + 6, k + 16, Blocks.leaves, 3, 1);
        world.setBlock(i + 9, j + 6, k + 17, Blocks.leaves, 3, 1);
        world.setBlock(i + 9, j + 6, k + 18, Blocks.leaves, 3, 1);
        world.setBlock(i + 9, j + 7, k + 3, Blocks.leaves, 3, 1);
        world.setBlock(i + 9, j + 7, k + 4, Blocks.leaves, 3, 1);
        world.setBlock(i + 9, j + 7, k + 5, Blocks.leaves, 3, 1);
        world.setBlock(i + 9, j + 7, k + 13, Blocks.leaves, 3, 1);
        world.setBlock(i + 9, j + 7, k + 14, Blocks.leaves, 3, 1);
        world.setBlock(i + 9, j + 7, k + 15, Blocks.leaves, 3, 1);
        world.setBlock(i + 9, j + 7, k + 16, Blocks.leaves, 3, 1);
        world.setBlock(i + 9, j + 7, k + 17, Blocks.leaves, 3, 1);
        world.setBlock(i + 9, j + 8, k + 16, Blocks.leaves, 3, 1);
        world.setBlock(i + 10, j + 0, k + 1, Blocks.stone_brick_stairs, 2, 1);
        world.setBlock(i + 10, j + 0, k + 2, Blocks.stonebrick);
        world.setBlock(i + 10, j + 0, k + 3, Blocks.stonebrick);
        world.setBlock(i + 10, j + 0, k + 4, Blocks.stonebrick, 1, 1);
        world.setBlock(i + 10, j + 0, k + 5, Blocks.stonebrick);
        world.setBlock(i + 10, j + 0, k + 6, Blocks.stonebrick, 1, 1);
        world.setBlock(i + 10, j + 0, k + 7, Blocks.stonebrick);
        world.setBlock(i + 10, j + 0, k + 8, Blocks.stonebrick);
        world.setBlock(i + 10, j + 0, k + 9, Blocks.stonebrick);
        world.setBlock(i + 10, j + 0, k + 10, Blocks.stonebrick);
        world.setBlock(i + 10, j + 0, k + 11, Blocks.stonebrick);
        world.setBlock(i + 10, j + 0, k + 12, Blocks.stonebrick);
        world.setBlock(i + 10, j + 0, k + 13, Blocks.stonebrick);
        world.setBlock(i + 10, j + 0, k + 14, Blocks.stonebrick);
        world.setBlock(i + 10, j + 0, k + 15, Blocks.stonebrick, 1, 1);
        world.setBlock(i + 10, j + 0, k + 16, Blocks.stonebrick);
        world.setBlock(i + 10, j + 0, k + 17, Blocks.stonebrick);
        world.setBlock(i + 10, j + 0, k + 18, Blocks.stonebrick);
        world.setBlock(i + 10, j + 0, k + 19, Blocks.stone_brick_stairs, 3, 1);
        world.setBlock(i + 10, j + 1, k + 9, Blocks.stone_brick_stairs, 2, 1);
        world.setBlock(i + 10, j + 1, k + 10, Blocks.stonebrick);
        world.setBlock(i + 10, j + 1, k + 11, Blocks.stone_brick_stairs, 3, 1);
        world.setBlock(i + 10, j + 2, k + 10, BlockManager.swordStoneInactive);
        world.setBlock(i + 10, j + 4, k + 2, Blocks.leaves, 3, 1);
        world.setBlock(i + 10, j + 4, k + 3, Blocks.leaves, 3, 1);
        world.setBlock(i + 10, j + 4, k + 4, Blocks.leaves, 3, 1);
        world.setBlock(i + 10, j + 4, k + 5, Blocks.leaves, 3, 1);
        world.setBlock(i + 10, j + 4, k + 6, Blocks.leaves, 3, 1);
        world.setBlock(i + 10, j + 5, k + 2, Blocks.leaves, 3, 1);
        world.setBlock(i + 10, j + 5, k + 3, Blocks.leaves, 3, 1);
        world.setBlock(i + 10, j + 5, k + 4, Blocks.leaves, 3, 1);
        world.setBlock(i + 10, j + 5, k + 5, Blocks.leaves, 3, 1);
        world.setBlock(i + 10, j + 5, k + 6, Blocks.leaves, 3, 1);
        world.setBlock(i + 10, j + 5, k + 14, Blocks.leaves, 3, 1);
        world.setBlock(i + 10, j + 5, k + 15, Blocks.leaves, 3, 1);
        world.setBlock(i + 10, j + 5, k + 16, Blocks.leaves, 3, 1);
        world.setBlock(i + 10, j + 5, k + 17, Blocks.leaves, 3, 1);
        world.setBlock(i + 10, j + 6, k + 4, Blocks.leaves, 3, 1);
        world.setBlock(i + 10, j + 6, k + 12, Blocks.leaves, 3, 1);
        world.setBlock(i + 10, j + 6, k + 13, Blocks.leaves, 3, 1);
        world.setBlock(i + 10, j + 6, k + 14, Blocks.leaves, 3, 1);
        world.setBlock(i + 10, j + 6, k + 15, Blocks.leaves, 3, 1);
        world.setBlock(i + 10, j + 6, k + 16, Blocks.leaves, 3, 1);
        world.setBlock(i + 10, j + 6, k + 17, Blocks.leaves, 3, 1);
        world.setBlock(i + 10, j + 6, k + 18, Blocks.leaves, 3, 1);
        world.setBlock(i + 10, j + 7, k + 4, Blocks.leaves, 3, 1);
        world.setBlock(i + 10, j + 7, k + 12, Blocks.leaves, 3, 1);
        world.setBlock(i + 10, j + 7, k + 13, Blocks.leaves, 3, 1);
        world.setBlock(i + 10, j + 7, k + 14, Blocks.leaves, 3, 1);
        world.setBlock(i + 10, j + 7, k + 15, Blocks.leaves, 3, 1);
        world.setBlock(i + 10, j + 7, k + 16, Blocks.leaves, 3, 1);
        world.setBlock(i + 10, j + 8, k + 13, Blocks.leaves, 3, 1);
        world.setBlock(i + 10, j + 8, k + 14, Blocks.leaves, 3, 1);
        world.setBlock(i + 10, j + 9, k + 14, Blocks.leaves, 3, 1);
        world.setBlock(i + 11, j + 0, k + 1, Blocks.stone_brick_stairs, 2, 1);
        world.setBlock(i + 11, j + 0, k + 2, Blocks.stonebrick);
        world.setBlock(i + 11, j + 0, k + 3, Blocks.stonebrick);
        world.setBlock(i + 11, j + 0, k + 4, Blocks.stonebrick);
        world.setBlock(i + 11, j + 0, k + 5, Blocks.stonebrick);
        world.setBlock(i + 11, j + 0, k + 6, Blocks.stonebrick);
        world.setBlock(i + 11, j + 0, k + 7, Blocks.stonebrick);
        world.setBlock(i + 11, j + 0, k + 8, Blocks.stonebrick);
        world.setBlock(i + 11, j + 0, k + 9, Blocks.stonebrick);
        world.setBlock(i + 11, j + 0, k + 10, Blocks.stonebrick);
        world.setBlock(i + 11, j + 0, k + 11, Blocks.stonebrick);
        world.setBlock(i + 11, j + 0, k + 12, Blocks.stonebrick);
        world.setBlock(i + 11, j + 0, k + 13, Blocks.stonebrick);
        world.setBlock(i + 11, j + 0, k + 14, Blocks.log, 3, 1);
        world.setBlock(i + 11, j + 0, k + 15, Blocks.stonebrick, 2, 1);
        world.setBlock(i + 11, j + 0, k + 16, Blocks.stonebrick);
        world.setBlock(i + 11, j + 0, k + 17, Blocks.stone_slab, 5, 1);
        world.setBlock(i + 11, j + 0, k + 18, Blocks.stonebrick);
        world.setBlock(i + 11, j + 0, k + 19, Blocks.stone_brick_stairs, 3, 1);
        world.setBlock(i + 11, j + 1, k + 9, Blocks.stone_brick_stairs, 1, 1);
        world.setBlock(i + 11, j + 1, k + 10, Blocks.stone_brick_stairs, 1, 1);
        world.setBlock(i + 11, j + 1, k + 11, Blocks.stone_brick_stairs, 3, 1);
        world.setBlock(i + 11, j + 1, k + 14, Blocks.log, 3, 1);
        world.setBlock(i + 11, j + 2, k + 14, Blocks.log, 3, 1);
        world.setBlock(i + 11, j + 3, k + 14, Blocks.log, 3, 1);
        world.setBlock(i + 11, j + 4, k + 3, Blocks.leaves, 3, 1);
        world.setBlock(i + 11, j + 4, k + 4, Blocks.leaves, 3, 1);
        world.setBlock(i + 11, j + 4, k + 5, Blocks.leaves, 3, 1);
        world.setBlock(i + 11, j + 4, k + 6, Blocks.leaves, 3, 1);
        world.setBlock(i + 11, j + 4, k + 14, Blocks.log, 3, 1);
        world.setBlock(i + 11, j + 5, k + 3, Blocks.leaves, 3, 1);
        world.setBlock(i + 11, j + 5, k + 4, Blocks.leaves, 3, 1);
        world.setBlock(i + 11, j + 5, k + 5, Blocks.leaves, 3, 1);
        world.setBlock(i + 11, j + 5, k + 14, Blocks.log, 3, 1);
        world.setBlock(i + 11, j + 6, k + 12, Blocks.leaves, 3, 1);
        world.setBlock(i + 11, j + 6, k + 13, Blocks.leaves, 3, 1);
        world.setBlock(i + 11, j + 6, k + 14, Blocks.log, 3, 1);
        world.setBlock(i + 11, j + 6, k + 15, Blocks.leaves, 3, 1);
        world.setBlock(i + 11, j + 6, k + 16, Blocks.leaves, 3, 1);
        world.setBlock(i + 11, j + 7, k + 12, Blocks.leaves, 3, 1);
        world.setBlock(i + 11, j + 7, k + 13, Blocks.leaves, 3, 1);
        world.setBlock(i + 11, j + 7, k + 14, Blocks.log, 3, 1);
        world.setBlock(i + 11, j + 7, k + 15, Blocks.leaves, 3, 1);
        world.setBlock(i + 11, j + 7, k + 16, Blocks.leaves, 3, 1);
        world.setBlock(i + 11, j + 8, k + 13, Blocks.leaves, 3, 1);
        world.setBlock(i + 11, j + 8, k + 14, Blocks.log, 3, 1);
        world.setBlock(i + 11, j + 8, k + 15, Blocks.leaves, 3, 1);
        world.setBlock(i + 11, j + 9, k + 13, Blocks.leaves, 3, 1);
        world.setBlock(i + 11, j + 9, k + 14, Blocks.leaves, 3, 1);
        world.setBlock(i + 11, j + 9, k + 15, Blocks.leaves, 3, 1);
        world.setBlock(i + 12, j + 0, k + 1, Blocks.stone_brick_stairs, 2, 1);
        world.setBlock(i + 12, j + 0, k + 2, Blocks.stonebrick);
        world.setBlock(i + 12, j + 0, k + 3, Blocks.stonebrick);
        world.setBlock(i + 12, j + 0, k + 4, Blocks.stonebrick);
        world.setBlock(i + 12, j + 0, k + 5, Blocks.stonebrick, 2, 1);
        world.setBlock(i + 12, j + 0, k + 6, Blocks.stonebrick);
        world.setBlock(i + 12, j + 0, k + 7, Blocks.stonebrick);
        world.setBlock(i + 12, j + 0, k + 8, Blocks.stonebrick);
        world.setBlock(i + 12, j + 0, k + 9, Blocks.stonebrick);
        world.setBlock(i + 12, j + 0, k + 10, Blocks.stonebrick);
        world.setBlock(i + 12, j + 0, k + 11, Blocks.stonebrick);
        world.setBlock(i + 12, j + 0, k + 12, Blocks.stonebrick);
        world.setBlock(i + 12, j + 0, k + 13, Blocks.stonebrick);
        world.setBlock(i + 12, j + 0, k + 14, Blocks.stonebrick);
        world.setBlock(i + 12, j + 0, k + 15, Blocks.stonebrick);
        world.setBlock(i + 12, j + 0, k + 16, Blocks.stonebrick);
        world.setBlock(i + 12, j + 0, k + 17, Blocks.stonebrick);
        world.setBlock(i + 12, j + 0, k + 18, Blocks.stone_brick_stairs, 1, 1);
        world.setBlock(i + 12, j + 0, k + 19, Blocks.stone_brick_stairs, 3, 1);
        world.setBlock(i + 12, j + 1, k + 8, Blocks.stonebrick);
        world.setBlock(i + 12, j + 1, k + 12, Blocks.stonebrick, 1, 1);
        world.setBlock(i + 12, j + 2, k + 8, Blocks.stonebrick, 2, 1);
        world.setBlock(i + 12, j + 2, k + 12, Blocks.stonebrick);
        world.setBlock(i + 12, j + 3, k + 8, Blocks.stonebrick, 3, 1);
        world.setBlock(i + 12, j + 3, k + 12, Blocks.stonebrick, 3, 1);
        world.setBlock(i + 12, j + 6, k + 12, Blocks.leaves, 3, 1);
        world.setBlock(i + 12, j + 6, k + 13, Blocks.leaves, 3, 1);
        world.setBlock(i + 12, j + 6, k + 14, Blocks.leaves, 3, 1);
        world.setBlock(i + 12, j + 6, k + 15, Blocks.leaves, 3, 1);
        world.setBlock(i + 12, j + 6, k + 16, Blocks.leaves, 3, 1);
        world.setBlock(i + 12, j + 7, k + 12, Blocks.leaves, 3, 1);
        world.setBlock(i + 12, j + 7, k + 13, Blocks.leaves, 3, 1);
        world.setBlock(i + 12, j + 7, k + 14, Blocks.leaves, 3, 1);
        world.setBlock(i + 12, j + 7, k + 15, Blocks.leaves, 3, 1);
        world.setBlock(i + 12, j + 7, k + 16, Blocks.leaves, 3, 1);
        world.setBlock(i + 12, j + 8, k + 14, Blocks.leaves, 3, 1);
        world.setBlock(i + 12, j + 8, k + 15, Blocks.leaves, 3, 1);
        world.setBlock(i + 12, j + 8, k + 16, Blocks.leaves, 3, 1);
        world.setBlock(i + 12, j + 9, k + 13, Blocks.leaves, 3, 1);
        world.setBlock(i + 12, j + 9, k + 14, Blocks.leaves, 3, 1);
        world.setBlock(i + 12, j + 9, k + 15, Blocks.leaves, 3, 1);
        world.setBlock(i + 12, j + 9, k + 16, Blocks.leaves, 3, 1);
        world.setBlock(i + 13, j + 0, k + 1, Blocks.stone_brick_stairs, 2, 1);
        world.setBlock(i + 13, j + 0, k + 2, Blocks.stone_brick_stairs, 1, 1);
        world.setBlock(i + 13, j + 0, k + 3, Blocks.stone_slab, 5, 1);
        world.setBlock(i + 13, j + 0, k + 4, Blocks.stonebrick);
        world.setBlock(i + 13, j + 0, k + 5, Blocks.stone_slab, 5, 1);
        world.setBlock(i + 13, j + 0, k + 6, Blocks.stonebrick);
        world.setBlock(i + 13, j + 0, k + 7, Blocks.stonebrick, 1, 1);
        world.setBlock(i + 13, j + 0, k + 8, Blocks.stone_slab, 5, 1);
        world.setBlock(i + 13, j + 0, k + 9, Blocks.stone_slab, 5, 1);
        world.setBlock(i + 13, j + 0, k + 10, Blocks.stonebrick);
        world.setBlock(i + 13, j + 0, k + 11, Blocks.stonebrick, 1, 1);
        world.setBlock(i + 13, j + 0, k + 12, Blocks.stonebrick);
        world.setBlock(i + 13, j + 0, k + 13, Blocks.stonebrick, 1, 1);
        world.setBlock(i + 13, j + 0, k + 14, Blocks.stonebrick);
        world.setBlock(i + 13, j + 0, k + 15, Blocks.stonebrick);
        world.setBlock(i + 13, j + 0, k + 16, Blocks.stonebrick, 1, 1);
        world.setBlock(i + 13, j + 0, k + 17, Blocks.stonebrick);
        world.setBlock(i + 13, j + 0, k + 18, Blocks.stone_brick_stairs, 3, 1);
        world.setBlock(i + 13, j + 6, k + 13, Blocks.leaves, 3, 1);
        world.setBlock(i + 13, j + 6, k + 14, Blocks.leaves, 3, 1);
        world.setBlock(i + 13, j + 6, k + 15, Blocks.leaves, 3, 1);
        world.setBlock(i + 13, j + 7, k + 13, Blocks.leaves, 3, 1);
        world.setBlock(i + 13, j + 7, k + 14, Blocks.leaves, 3, 1);
        world.setBlock(i + 13, j + 7, k + 15, Blocks.leaves, 3, 1);
        world.setBlock(i + 13, j + 8, k + 13, Blocks.leaves, 3, 1);
        world.setBlock(i + 13, j + 8, k + 14, Blocks.leaves, 3, 1);
        world.setBlock(i + 13, j + 8, k + 15, Blocks.leaves, 3, 1);
        world.setBlock(i + 13, j + 8, k + 16, Blocks.leaves, 3, 1);
        world.setBlock(i + 13, j + 8, k + 17, Blocks.leaves, 3, 1);
        world.setBlock(i + 13, j + 9, k + 13, Blocks.leaves, 3, 1);
        world.setBlock(i + 13, j + 9, k + 14, Blocks.leaves, 3, 1);
        world.setBlock(i + 13, j + 9, k + 15, Blocks.leaves, 3, 1);
        world.setBlock(i + 13, j + 9, k + 16, Blocks.leaves, 3, 1);
        world.setBlock(i + 13, j + 9, k + 17, Blocks.leaves, 3, 1);
        world.setBlock(i + 13, j + 10, k + 14, Blocks.leaves, 3, 1);
        world.setBlock(i + 13, j + 10, k + 15, Blocks.leaves, 3, 1);
        world.setBlock(i + 13, j + 10, k + 16, Blocks.leaves, 3, 1);
        world.setBlock(i + 13, j + 11, k + 15, Blocks.leaves, 3, 1);
        world.setBlock(i + 14, j + 0, k + 2, Blocks.stone_brick_stairs, 2, 1);
        world.setBlock(i + 14, j + 0, k + 3, Blocks.stonebrick);
        world.setBlock(i + 14, j + 0, k + 4, Blocks.stonebrick);
        world.setBlock(i + 14, j + 0, k + 5, Blocks.stone_slab, 5, 1);
        world.setBlock(i + 14, j + 0, k + 6, Blocks.stonebrick, 1, 1);
        world.setBlock(i + 14, j + 0, k + 7, Blocks.stone_slab, 5, 1);
        world.setBlock(i + 14, j + 0, k + 8, Blocks.stone_slab, 5, 1);
        world.setBlock(i + 14, j + 0, k + 9, Blocks.stonebrick, 2, 1);
        world.setBlock(i + 14, j + 0, k + 10, Blocks.stonebrick, 1, 1);
        world.setBlock(i + 14, j + 0, k + 11, Blocks.stonebrick);
        world.setBlock(i + 14, j + 0, k + 12, Blocks.stonebrick);
        world.setBlock(i + 14, j + 0, k + 13, Blocks.stonebrick);
        world.setBlock(i + 14, j + 0, k + 14, Blocks.stone_slab, 5, 1);
        world.setBlock(i + 14, j + 0, k + 15, Blocks.log, 3, 1);
        world.setBlock(i + 14, j + 0, k + 16, Blocks.stonebrick);
        world.setBlock(i + 14, j + 0, k + 17, Blocks.stonebrick);
        world.setBlock(i + 14, j + 0, k + 18, Blocks.stone_brick_stairs, 3, 1);
        world.setBlock(i + 14, j + 1, k + 15, Blocks.log, 3, 1);
        world.setBlock(i + 14, j + 2, k + 2, Blocks.leaves, 3, 1);
        world.setBlock(i + 14, j + 2, k + 3, Blocks.leaves, 3, 1);
        world.setBlock(i + 14, j + 2, k + 4, Blocks.leaves, 3, 1);
        world.setBlock(i + 14, j + 2, k + 5, Blocks.leaves, 3, 1);
        world.setBlock(i + 14, j + 2, k + 6, Blocks.leaves, 3, 1);
        world.setBlock(i + 14, j + 2, k + 15, Blocks.log, 3, 1);
        world.setBlock(i + 14, j + 3, k + 3, Blocks.leaves, 3, 1);
        world.setBlock(i + 14, j + 3, k + 4, Blocks.leaves, 3, 1);
        world.setBlock(i + 14, j + 3, k + 5, Blocks.leaves, 3, 1);
        world.setBlock(i + 14, j + 3, k + 15, Blocks.log, 3, 1);
        world.setBlock(i + 14, j + 4, k + 15, Blocks.log, 3, 1);
        world.setBlock(i + 14, j + 5, k + 15, Blocks.log, 3, 1);
        world.setBlock(i + 14, j + 6, k + 15, Blocks.log, 3, 1);
        world.setBlock(i + 14, j + 7, k + 15, Blocks.log, 3, 1);
        world.setBlock(i + 14, j + 8, k + 13, Blocks.leaves, 3, 1);
        world.setBlock(i + 14, j + 8, k + 14, Blocks.leaves, 3, 1);
        world.setBlock(i + 14, j + 8, k + 15, Blocks.log, 3, 1);
        world.setBlock(i + 14, j + 8, k + 16, Blocks.leaves, 3, 1);
        world.setBlock(i + 14, j + 8, k + 17, Blocks.leaves, 3, 1);
        world.setBlock(i + 14, j + 9, k + 8, Blocks.leaves, 3, 1);
        world.setBlock(i + 14, j + 9, k + 9, Blocks.leaves, 3, 1);
        world.setBlock(i + 14, j + 9, k + 10, Blocks.leaves, 3, 1);
        world.setBlock(i + 14, j + 9, k + 11, Blocks.leaves, 3, 1);
        world.setBlock(i + 14, j + 9, k + 13, Blocks.leaves, 3, 1);
        world.setBlock(i + 14, j + 9, k + 14, Blocks.leaves, 3, 1);
        world.setBlock(i + 14, j + 9, k + 15, Blocks.log, 3, 1);
        world.setBlock(i + 14, j + 9, k + 16, Blocks.leaves, 3, 1);
        world.setBlock(i + 14, j + 9, k + 17, Blocks.leaves, 3, 1);
        world.setBlock(i + 14, j + 10, k + 8, Blocks.leaves, 3, 1);
        world.setBlock(i + 14, j + 10, k + 9, Blocks.leaves, 3, 1);
        world.setBlock(i + 14, j + 10, k + 10, Blocks.leaves, 3, 1);
        world.setBlock(i + 14, j + 10, k + 11, Blocks.leaves, 3, 1);
        world.setBlock(i + 14, j + 10, k + 12, Blocks.leaves, 3, 1);
        world.setBlock(i + 14, j + 10, k + 14, Blocks.leaves, 3, 1);
        world.setBlock(i + 14, j + 10, k + 15, Blocks.log, 3, 1);
        world.setBlock(i + 14, j + 10, k + 16, Blocks.leaves, 3, 1);
        world.setBlock(i + 14, j + 11, k + 14, Blocks.leaves, 3, 1);
        world.setBlock(i + 14, j + 11, k + 15, Blocks.leaves, 3, 1);
        world.setBlock(i + 14, j + 11, k + 16, Blocks.leaves, 3, 1);
        world.setBlock(i + 15, j + 0, k + 2, Blocks.stone_brick_stairs, 2, 1);
        world.setBlock(i + 15, j + 0, k + 3, Blocks.stonebrick);
        world.setBlock(i + 15, j + 0, k + 4, Blocks.stonebrick);
        world.setBlock(i + 15, j + 0, k + 5, Blocks.stonebrick);
        world.setBlock(i + 15, j + 0, k + 6, Blocks.stonebrick, 2, 1);
        world.setBlock(i + 15, j + 0, k + 7, Blocks.stonebrick);
        world.setBlock(i + 15, j + 0, k + 8, Blocks.stonebrick);
        world.setBlock(i + 15, j + 0, k + 9, Blocks.stonebrick, 1, 1);
        world.setBlock(i + 15, j + 0, k + 10, Blocks.stonebrick);
        world.setBlock(i + 15, j + 0, k + 11, Blocks.stonebrick, 2, 1);
        world.setBlock(i + 15, j + 0, k + 12, Blocks.stonebrick, 1, 1);
        world.setBlock(i + 15, j + 0, k + 13, Blocks.stone_slab, 5, 1);
        world.setBlock(i + 15, j + 0, k + 14, Blocks.stone_slab, 5, 1);
        world.setBlock(i + 15, j + 0, k + 15, Blocks.stonebrick);
        world.setBlock(i + 15, j + 0, k + 16, Blocks.stonebrick);
        world.setBlock(i + 15, j + 0, k + 17, Blocks.stone_brick_stairs, 1, 1);
        world.setBlock(i + 15, j + 0, k + 18, Blocks.stone_brick_stairs, 3, 1);
        world.setBlock(i + 15, j + 2, k + 2, Blocks.leaves, 3, 1);
        world.setBlock(i + 15, j + 2, k + 3, Blocks.leaves, 3, 1);
        world.setBlock(i + 15, j + 2, k + 4, Blocks.leaves, 3, 1);
        world.setBlock(i + 15, j + 2, k + 5, Blocks.leaves, 3, 1);
        world.setBlock(i + 15, j + 2, k + 6, Blocks.leaves, 3, 1);
        world.setBlock(i + 15, j + 3, k + 2, Blocks.leaves, 3, 1);
        world.setBlock(i + 15, j + 3, k + 3, Blocks.leaves, 3, 1);
        world.setBlock(i + 15, j + 3, k + 4, Blocks.leaves, 3, 1);
        world.setBlock(i + 15, j + 3, k + 5, Blocks.leaves, 3, 1);
        world.setBlock(i + 15, j + 3, k + 6, Blocks.leaves, 3, 1);
        world.setBlock(i + 15, j + 4, k + 4, Blocks.leaves, 3, 1);
        world.setBlock(i + 15, j + 5, k + 4, Blocks.leaves, 3, 1);
        world.setBlock(i + 15, j + 8, k + 13, Blocks.leaves, 3, 1);
        world.setBlock(i + 15, j + 8, k + 14, Blocks.leaves, 3, 1);
        world.setBlock(i + 15, j + 8, k + 15, Blocks.leaves, 3, 1);
        world.setBlock(i + 15, j + 8, k + 16, Blocks.leaves, 3, 1);
        world.setBlock(i + 15, j + 8, k + 17, Blocks.leaves, 3, 1);
        world.setBlock(i + 15, j + 9, k + 8, Blocks.leaves, 3, 1);
        world.setBlock(i + 15, j + 9, k + 9, Blocks.leaves, 3, 1);
        world.setBlock(i + 15, j + 9, k + 10, Blocks.leaves, 3, 1);
        world.setBlock(i + 15, j + 9, k + 11, Blocks.leaves, 3, 1);
        world.setBlock(i + 15, j + 9, k + 12, Blocks.leaves, 3, 1);
        world.setBlock(i + 15, j + 9, k + 13, Blocks.leaves, 3, 1);
        world.setBlock(i + 15, j + 9, k + 14, Blocks.leaves, 3, 1);
        world.setBlock(i + 15, j + 9, k + 15, Blocks.leaves, 3, 1);
        world.setBlock(i + 15, j + 9, k + 16, Blocks.leaves, 3, 1);
        world.setBlock(i + 15, j + 9, k + 17, Blocks.leaves, 3, 1);
        world.setBlock(i + 15, j + 10, k + 8, Blocks.leaves, 3, 1);
        world.setBlock(i + 15, j + 10, k + 9, Blocks.leaves, 3, 1);
        world.setBlock(i + 15, j + 10, k + 10, Blocks.leaves, 3, 1);
        world.setBlock(i + 15, j + 10, k + 11, Blocks.leaves, 3, 1);
        world.setBlock(i + 15, j + 10, k + 12, Blocks.leaves, 3, 1);
        world.setBlock(i + 15, j + 10, k + 14, Blocks.leaves, 3, 1);
        world.setBlock(i + 15, j + 10, k + 15, Blocks.leaves, 3, 1);
        world.setBlock(i + 15, j + 11, k + 10, Blocks.leaves, 3, 1);
        world.setBlock(i + 15, j + 11, k + 11, Blocks.leaves, 3, 1);
        world.setBlock(i + 15, j + 11, k + 15, Blocks.leaves, 3, 1);
        world.setBlock(i + 15, j + 12, k + 10, Blocks.leaves, 3, 1);
        world.setBlock(i + 16, j + 0, k + 2, Blocks.stone_brick_stairs, 2, 1);
        world.setBlock(i + 16, j + 0, k + 3, Blocks.stone_brick_stairs, 1, 1);
        world.setBlock(i + 16, j + 0, k + 4, Blocks.log, 3, 1);
        world.setBlock(i + 16, j + 0, k + 5, Blocks.stonebrick);
        world.setBlock(i + 16, j + 0, k + 6, Blocks.stonebrick);
        world.setBlock(i + 16, j + 0, k + 7, Blocks.stonebrick);
        world.setBlock(i + 16, j + 0, k + 8, Blocks.stonebrick);
        world.setBlock(i + 16, j + 0, k + 9, Blocks.stonebrick);
        world.setBlock(i + 16, j + 0, k + 10, Blocks.log, 3, 1);
        world.setBlock(i + 16, j + 0, k + 11, Blocks.stonebrick, 2, 1);
        world.setBlock(i + 16, j + 0, k + 12, Blocks.stonebrick);
        world.setBlock(i + 16, j + 0, k + 13, Blocks.stonebrick);
        world.setBlock(i + 16, j + 0, k + 14, Blocks.stonebrick, 2, 1);
        world.setBlock(i + 16, j + 0, k + 15, Blocks.stonebrick);
        world.setBlock(i + 16, j + 0, k + 16, Blocks.stonebrick);
        world.setBlock(i + 16, j + 0, k + 17, Blocks.stone_brick_stairs, 3, 1);
        world.setBlock(i + 16, j + 1, k + 4, Blocks.log, 3, 1);
        world.setBlock(i + 16, j + 1, k + 10, Blocks.log, 3, 1);
        world.setBlock(i + 16, j + 2, k + 2, Blocks.leaves, 3, 1);
        world.setBlock(i + 16, j + 2, k + 3, Blocks.leaves, 3, 1);
        world.setBlock(i + 16, j + 2, k + 4, Blocks.log, 3, 1);
        world.setBlock(i + 16, j + 2, k + 5, Blocks.leaves, 3, 1);
        world.setBlock(i + 16, j + 2, k + 6, Blocks.leaves, 3, 1);
        world.setBlock(i + 16, j + 2, k + 10, Blocks.log, 3, 1);
        world.setBlock(i + 16, j + 3, k + 2, Blocks.leaves, 3, 1);
        world.setBlock(i + 16, j + 3, k + 3, Blocks.leaves, 3, 1);
        world.setBlock(i + 16, j + 3, k + 4, Blocks.log, 3, 1);
        world.setBlock(i + 16, j + 3, k + 5, Blocks.leaves, 3, 1);
        world.setBlock(i + 16, j + 3, k + 6, Blocks.leaves, 3, 1);
        world.setBlock(i + 16, j + 3, k + 10, Blocks.log, 3, 1);
        world.setBlock(i + 16, j + 4, k + 3, Blocks.leaves, 3, 1);
        world.setBlock(i + 16, j + 4, k + 4, Blocks.log, 3, 1);
        world.setBlock(i + 16, j + 4, k + 5, Blocks.leaves, 3, 1);
        world.setBlock(i + 16, j + 4, k + 10, Blocks.log, 3, 1);
        world.setBlock(i + 16, j + 5, k + 3, Blocks.leaves, 3, 1);
        world.setBlock(i + 16, j + 5, k + 4, Blocks.leaves, 3, 1);
        world.setBlock(i + 16, j + 5, k + 5, Blocks.leaves, 3, 1);
        world.setBlock(i + 16, j + 5, k + 10, Blocks.log, 3, 1);
        world.setBlock(i + 16, j + 6, k + 10, Blocks.log, 3, 1);
        world.setBlock(i + 16, j + 7, k + 10, Blocks.log, 3, 1);
        world.setBlock(i + 16, j + 8, k + 10, Blocks.log, 3, 1);
        world.setBlock(i + 16, j + 8, k + 14, Blocks.leaves, 3, 1);
        world.setBlock(i + 16, j + 8, k + 15, Blocks.leaves, 3, 1);
        world.setBlock(i + 16, j + 8, k + 16, Blocks.leaves, 3, 1);
        world.setBlock(i + 16, j + 8, k + 17, Blocks.leaves, 3, 1);
        world.setBlock(i + 16, j + 9, k + 8, Blocks.leaves, 3, 1);
        world.setBlock(i + 16, j + 9, k + 9, Blocks.leaves, 3, 1);
        world.setBlock(i + 16, j + 9, k + 10, Blocks.log, 3, 1);
        world.setBlock(i + 16, j + 9, k + 11, Blocks.leaves, 3, 1);
        world.setBlock(i + 16, j + 9, k + 12, Blocks.leaves, 3, 1);
        world.setBlock(i + 16, j + 9, k + 13, Blocks.leaves, 3, 1);
        world.setBlock(i + 16, j + 9, k + 14, Blocks.leaves, 3, 1);
        world.setBlock(i + 16, j + 9, k + 15, Blocks.leaves, 3, 1);
        world.setBlock(i + 16, j + 9, k + 16, Blocks.leaves, 3, 1);
        world.setBlock(i + 16, j + 10, k + 8, Blocks.leaves, 3, 1);
        world.setBlock(i + 16, j + 10, k + 9, Blocks.leaves, 3, 1);
        world.setBlock(i + 16, j + 10, k + 10, Blocks.log, 3, 1);
        world.setBlock(i + 16, j + 10, k + 11, Blocks.leaves, 3, 1);
        world.setBlock(i + 16, j + 10, k + 12, Blocks.leaves, 3, 1);
        world.setBlock(i + 16, j + 11, k + 9, Blocks.leaves, 3, 1);
        world.setBlock(i + 16, j + 11, k + 10, Blocks.log, 3, 1);
        world.setBlock(i + 16, j + 11, k + 11, Blocks.leaves, 3, 1);
        world.setBlock(i + 16, j + 12, k + 9, Blocks.leaves, 3, 1);
        world.setBlock(i + 16, j + 12, k + 10, Blocks.leaves, 3, 1);
        world.setBlock(i + 16, j + 12, k + 11, Blocks.leaves, 3, 1);
        world.setBlock(i + 17, j + 0, k + 3, Blocks.stone_brick_stairs, 2, 1);
        world.setBlock(i + 17, j + 0, k + 4, Blocks.stonebrick);
        world.setBlock(i + 17, j + 0, k + 5, Blocks.stonebrick);
        world.setBlock(i + 17, j + 0, k + 6, Blocks.stonebrick);
        world.setBlock(i + 17, j + 0, k + 7, Blocks.stonebrick);
        world.setBlock(i + 17, j + 0, k + 8, Blocks.stone_slab, 5, 1);
        world.setBlock(i + 17, j + 0, k + 9, Blocks.stone_slab, 5, 1);
        world.setBlock(i + 17, j + 0, k + 10, Blocks.stonebrick);
        world.setBlock(i + 17, j + 0, k + 11, Blocks.stonebrick);
        world.setBlock(i + 17, j + 0, k + 12, Blocks.stonebrick);
        world.setBlock(i + 17, j + 0, k + 13, Blocks.stonebrick, 2, 1);
        world.setBlock(i + 17, j + 0, k + 14, Blocks.stonebrick);
        world.setBlock(i + 17, j + 0, k + 15, Blocks.stonebrick);
        world.setBlock(i + 17, j + 0, k + 16, Blocks.stonebrick);
        world.setBlock(i + 17, j + 0, k + 17, Blocks.stone_brick_stairs, 3, 1);
        world.setBlock(i + 17, j + 2, k + 2, Blocks.leaves, 3, 1);
        world.setBlock(i + 17, j + 2, k + 3, Blocks.leaves, 3, 1);
        world.setBlock(i + 17, j + 2, k + 4, Blocks.leaves, 3, 1);
        world.setBlock(i + 17, j + 2, k + 5, Blocks.leaves, 3, 1);
        world.setBlock(i + 17, j + 2, k + 6, Blocks.leaves, 3, 1);
        world.setBlock(i + 17, j + 3, k + 2, Blocks.leaves, 3, 1);
        world.setBlock(i + 17, j + 3, k + 3, Blocks.leaves, 3, 1);
        world.setBlock(i + 17, j + 3, k + 4, Blocks.leaves, 3, 1);
        world.setBlock(i + 17, j + 3, k + 5, Blocks.leaves, 3, 1);
        world.setBlock(i + 17, j + 3, k + 6, Blocks.leaves, 3, 1);
        world.setBlock(i + 17, j + 4, k + 3, Blocks.leaves, 3, 1);
        world.setBlock(i + 17, j + 4, k + 4, Blocks.leaves, 3, 1);
        world.setBlock(i + 17, j + 4, k + 5, Blocks.leaves, 3, 1);
        world.setBlock(i + 17, j + 5, k + 4, Blocks.leaves, 3, 1);
        world.setBlock(i + 17, j + 9, k + 8, Blocks.leaves, 3, 1);
        world.setBlock(i + 17, j + 9, k + 9, Blocks.leaves, 3, 1);
        world.setBlock(i + 17, j + 9, k + 10, Blocks.leaves, 3, 1);
        world.setBlock(i + 17, j + 9, k + 11, Blocks.leaves, 3, 1);
        world.setBlock(i + 17, j + 9, k + 12, Blocks.leaves, 3, 1);
        world.setBlock(i + 17, j + 10, k + 8, Blocks.leaves, 3, 1);
        world.setBlock(i + 17, j + 10, k + 9, Blocks.leaves, 3, 1);
        world.setBlock(i + 17, j + 10, k + 10, Blocks.leaves, 3, 1);
        world.setBlock(i + 17, j + 10, k + 11, Blocks.leaves, 3, 1);
        world.setBlock(i + 17, j + 10, k + 12, Blocks.leaves, 3, 1);
        world.setBlock(i + 17, j + 11, k + 10, Blocks.leaves, 3, 1);
        world.setBlock(i + 17, j + 11, k + 11, Blocks.leaves, 3, 1);
        world.setBlock(i + 17, j + 12, k + 10, Blocks.leaves, 3, 1);
        world.setBlock(i + 18, j + 0, k + 3, Blocks.stone_brick_stairs, 2, 1);
        world.setBlock(i + 18, j + 0, k + 4, Blocks.stone_brick_stairs, 1, 1);
        world.setBlock(i + 18, j + 0, k + 5, Blocks.stone_brick_stairs, 1, 1);
        world.setBlock(i + 18, j + 0, k + 6, Blocks.stone_brick_stairs, 1, 1);
        world.setBlock(i + 18, j + 0, k + 7, Blocks.stone_brick_stairs, 2, 1);
        world.setBlock(i + 18, j + 0, k + 8, Blocks.stone_slab, 5, 1);
        world.setBlock(i + 18, j + 0, k + 9, Blocks.stonebrick);
        world.setBlock(i + 18, j + 0, k + 10, Blocks.stonebrick);
        world.setBlock(i + 18, j + 0, k + 11, Blocks.stonebrick);
        world.setBlock(i + 18, j + 0, k + 12, Blocks.stonebrick);
        world.setBlock(i + 18, j + 0, k + 13, Blocks.stone_brick_stairs, 3, 1);
        world.setBlock(i + 18, j + 0, k + 14, Blocks.stone_brick_stairs, 1, 1);
        world.setBlock(i + 18, j + 0, k + 15, Blocks.stone_brick_stairs, 1, 1);
        world.setBlock(i + 18, j + 0, k + 16, Blocks.stone_brick_stairs, 1, 1);
        world.setBlock(i + 18, j + 0, k + 17, Blocks.stone_brick_stairs, 3, 1);
        world.setBlock(i + 18, j + 2, k + 3, Blocks.leaves, 3, 1);
        world.setBlock(i + 18, j + 2, k + 4, Blocks.leaves, 3, 1);
        world.setBlock(i + 18, j + 2, k + 5, Blocks.leaves, 3, 1);
        world.setBlock(i + 18, j + 2, k + 6, Blocks.leaves, 3, 1);
        world.setBlock(i + 18, j + 3, k + 2, Blocks.leaves, 3, 1);
        world.setBlock(i + 18, j + 3, k + 3, Blocks.leaves, 3, 1);
        world.setBlock(i + 18, j + 3, k + 4, Blocks.leaves, 3, 1);
        world.setBlock(i + 18, j + 3, k + 5, Blocks.leaves, 3, 1);
        world.setBlock(i + 18, j + 3, k + 6, Blocks.leaves, 3, 1);
        world.setBlock(i + 18, j + 9, k + 9, Blocks.leaves, 3, 1);
        world.setBlock(i + 18, j + 9, k + 10, Blocks.leaves, 3, 1);
        world.setBlock(i + 18, j + 9, k + 11, Blocks.leaves, 3, 1);
        world.setBlock(i + 18, j + 10, k + 9, Blocks.leaves, 3, 1);
        world.setBlock(i + 18, j + 10, k + 10, Blocks.leaves, 3, 1);
        world.setBlock(i + 18, j + 10, k + 11, Blocks.leaves, 3, 1);
        world.setBlock(i + 19, j + 0, k + 7, Blocks.stone_brick_stairs, 1, 1);
        world.setBlock(i + 19, j + 0, k + 8, Blocks.stone_brick_stairs, 1, 1);
        world.setBlock(i + 19, j + 0, k + 9, Blocks.stone_brick_stairs, 1, 1);
        world.setBlock(i + 19, j + 0, k + 10, Blocks.stone_brick_stairs, 1, 1);
        world.setBlock(i + 19, j + 0, k + 11, Blocks.stone_brick_stairs, 1, 1);
        world.setBlock(i + 19, j + 0, k + 12, Blocks.stone_brick_stairs, 1, 1);
        world.setBlock(i + 19, j + 0, k + 13, Blocks.stone_brick_stairs, 1, 1);
        world.setBlock(i + 0, j + 1, k + 8, Blocks.vine, 8, 1);
        world.setBlock(i + 0, j + 1, k + 9, Blocks.vine, 8, 1);
        world.setBlock(i + 0, j + 2, k + 8, Blocks.vine, 8, 1);
        world.setBlock(i + 0, j + 2, k + 9, Blocks.vine, 8, 1);
        world.setBlock(i + 0, j + 2, k + 14, Blocks.vine, 8, 1);
        world.setBlock(i + 0, j + 3, k + 8, Blocks.vine, 8, 1);
        world.setBlock(i + 0, j + 3, k + 9, Blocks.vine, 8, 1);
        world.setBlock(i + 0, j + 3, k + 14, Blocks.vine, 8, 1);
        world.setBlock(i + 0, j + 3, k + 15, Blocks.vine, 8, 1);
        world.setBlock(i + 0, j + 4, k + 12, Blocks.vine, 8, 1);
        world.setBlock(i + 0, j + 4, k + 14, Blocks.vine, 8, 1);
        world.setBlock(i + 0, j + 4, k + 15, Blocks.vine, 8, 1);
        world.setBlock(i + 0, j + 5, k + 12, Blocks.vine, 8, 1);
        world.setBlock(i + 0, j + 5, k + 14, Blocks.vine, 8, 1);
        world.setBlock(i + 0, j + 5, k + 15, Blocks.vine, 8, 1);
        world.setBlock(i + 0, j + 6, k + 12, Blocks.vine, 8, 1);
        world.setBlock(i + 0, j + 6, k + 13, Blocks.vine, 8, 1);
        world.setBlock(i + 0, j + 6, k + 14, Blocks.vine, 8, 1);
        world.setBlock(i + 0, j + 6, k + 15, Blocks.vine, 8, 1);
        world.setBlock(i + 1, j + 3, k + 6, Blocks.vine, 1, 1);
        world.setBlock(i + 1, j + 5, k + 11, Blocks.vine, 1, 1);
        world.setBlock(i + 1, j + 6, k + 11, Blocks.vine, 1, 1);
        world.setBlock(i + 1, j + 6, k + 17, Blocks.vine, 4, 1);
        world.setBlock(i + 1, j + 7, k + 12, Blocks.vine, 8, 1);
        world.setBlock(i + 2, j + 1, k + 6, Blocks.vine, 1, 1);
        world.setBlock(i + 2, j + 1, k + 9, Blocks.vine, 8, 1);
        world.setBlock(i + 2, j + 1, k + 12, Blocks.vine, 4, 1);
        world.setBlock(i + 2, j + 1, k + 17, Blocks.vine, 4, 1);
        world.setBlock(i + 2, j + 2, k + 6, Blocks.vine, 1, 1);
        world.setBlock(i + 2, j + 2, k + 9, Blocks.vine, 8, 1);
        world.setBlock(i + 2, j + 2, k + 12, Blocks.vine, 4, 1);
        world.setBlock(i + 2, j + 2, k + 17, Blocks.vine, 4, 1);
        world.setBlock(i + 2, j + 3, k + 6, Blocks.vine, 1, 1);
        world.setBlock(i + 2, j + 3, k + 12, Blocks.vine, 4, 1);
        world.setBlock(i + 2, j + 3, k + 17, Blocks.vine, 4, 1);
        world.setBlock(i + 2, j + 4, k + 14, Blocks.vine, 8, 1);
        world.setBlock(i + 2, j + 4, k + 17, Blocks.vine, 4, 1);
        world.setBlock(i + 2, j + 5, k + 11, Blocks.vine, 1, 1);
        world.setBlock(i + 2, j + 5, k + 14, Blocks.vine, 8, 1);
        world.setBlock(i + 2, j + 5, k + 17, Blocks.vine, 4, 1);
        world.setBlock(i + 2, j + 6, k + 11, Blocks.vine, 1, 1);
        world.setBlock(i + 2, j + 6, k + 17, Blocks.vine, 4, 1);
        world.setBlock(i + 2, j + 7, k + 11, Blocks.vine, 1, 1);
        world.setBlock(i + 3, j + 1, k + 10, Blocks.brown_mushroom);
        world.setBlock(i + 3, j + 1, k + 12, Blocks.brown_mushroom);
        world.setBlock(i + 3, j + 2, k + 8, Blocks.vine, 1, 1);
        world.setBlock(i + 3, j + 2, k + 12, Blocks.vine, 4, 1);
        world.setBlock(i + 3, j + 2, k + 17, Blocks.vine, 4, 1);
        world.setBlock(i + 3, j + 3, k + 12, Blocks.vine, 4, 1);
        world.setBlock(i + 3, j + 3, k + 13, Blocks.vine, 1, 1);
        world.setBlock(i + 3, j + 3, k + 17, Blocks.vine, 4, 1);
        world.setBlock(i + 3, j + 4, k + 13, Blocks.vine, 1, 1);
        world.setBlock(i + 3, j + 4, k + 17, Blocks.vine, 4, 1);
        world.setBlock(i + 3, j + 5, k + 11, Blocks.vine, 1, 1);
        world.setBlock(i + 3, j + 5, k + 13, Blocks.vine, 1, 1);
        world.setBlock(i + 3, j + 5, k + 15, Blocks.vine, 4, 1);
        world.setBlock(i + 3, j + 5, k + 17, Blocks.vine, 4, 1);
        world.setBlock(i + 3, j + 6, k + 11, Blocks.vine, 1, 1);
        world.setBlock(i + 3, j + 6, k + 17, Blocks.vine, 4, 1);
        world.setBlock(i + 3, j + 7, k + 11, Blocks.vine, 1, 1);
        world.setBlock(i + 4, j + 1, k + 12, Blocks.vine, 4, 1);
        world.setBlock(i + 4, j + 1, k + 14, Blocks.red_mushroom);
        world.setBlock(i + 4, j + 2, k + 6, Blocks.vine, 1, 1);
        world.setBlock(i + 4, j + 2, k + 12, Blocks.vine, 4, 1);
        world.setBlock(i + 4, j + 3, k + 6, Blocks.vine, 1, 1);
        world.setBlock(i + 4, j + 3, k + 12, Blocks.vine, 4, 1);
        world.setBlock(i + 4, j + 3, k + 17, Blocks.vine, 4, 1);
        world.setBlock(i + 4, j + 4, k + 17, Blocks.vine, 4, 1);
        world.setBlock(i + 4, j + 5, k + 17, Blocks.vine, 4, 1);
        world.setBlock(i + 4, j + 6, k + 17, Blocks.vine, 4, 1);
        world.setBlock(i + 5, j + 1, k + 11, Blocks.vine, 4, 1);
        world.setBlock(i + 5, j + 1, k + 16, Blocks.vine, 8, 1);
        world.setBlock(i + 5, j + 1, k + 17, Blocks.vine, 8, 1);
        world.setBlock(i + 5, j + 1, k + 18, Blocks.vine, 8, 1);
        world.setBlock(i + 5, j + 2, k + 11, Blocks.vine, 4, 1);
        world.setBlock(i + 5, j + 2, k + 16, Blocks.vine, 8, 1);
        world.setBlock(i + 5, j + 2, k + 17, Blocks.vine, 8, 1);
        world.setBlock(i + 5, j + 2, k + 18, Blocks.vine, 8, 1);
        world.setBlock(i + 5, j + 3, k + 6, Blocks.vine, 1, 1);
        world.setBlock(i + 5, j + 3, k + 11, Blocks.vine, 4, 1);
        world.setBlock(i + 5, j + 3, k + 15, Blocks.vine, 8, 1);
        world.setBlock(i + 5, j + 3, k + 16, Blocks.vine, 8, 1);
        world.setBlock(i + 5, j + 3, k + 17, Blocks.vine, 12, 1);
        world.setBlock(i + 5, j + 3, k + 18, Blocks.vine, 8, 1);
        world.setBlock(i + 5, j + 4, k + 15, Blocks.vine, 8, 1);
        world.setBlock(i + 5, j + 4, k + 16, Blocks.vine, 8, 1);
        world.setBlock(i + 5, j + 4, k + 17, Blocks.vine, 12, 1);
        world.setBlock(i + 5, j + 4, k + 18, Blocks.vine, 8, 1);
        world.setBlock(i + 5, j + 5, k + 11, Blocks.vine, 1, 1);
        world.setBlock(i + 5, j + 5, k + 14, Blocks.vine, 8, 1);
        world.setBlock(i + 5, j + 5, k + 15, Blocks.vine, 8, 1);
        world.setBlock(i + 5, j + 5, k + 16, Blocks.vine, 8, 1);
        world.setBlock(i + 5, j + 5, k + 17, Blocks.vine, 12, 1);
        world.setBlock(i + 5, j + 5, k + 18, Blocks.vine, 8, 1);
        world.setBlock(i + 5, j + 6, k + 11, Blocks.vine, 1, 1);
        world.setBlock(i + 5, j + 6, k + 17, Blocks.vine, 4, 1);
        world.setBlock(i + 5, j + 7, k + 11, Blocks.vine, 1, 1);
        world.setBlock(i + 6, j + 1, k + 2, Blocks.vine, 8, 1);
        world.setBlock(i + 6, j + 1, k + 4, Blocks.vine, 8, 1);
        world.setBlock(i + 6, j + 1, k + 6, Blocks.vine, 8, 1);
        world.setBlock(i + 6, j + 1, k + 7, Blocks.vine, 2, 1);
        world.setBlock(i + 6, j + 1, k + 9, Blocks.vine, 2, 1);
        world.setBlock(i + 6, j + 1, k + 10, Blocks.vine, 2, 1);
        world.setBlock(i + 6, j + 2, k + 2, Blocks.vine, 8, 1);
        world.setBlock(i + 6, j + 2, k + 4, Blocks.vine, 8, 1);
        world.setBlock(i + 6, j + 2, k + 6, Blocks.vine, 8, 1);
        world.setBlock(i + 6, j + 2, k + 7, Blocks.vine, 2, 1);
        world.setBlock(i + 6, j + 2, k + 9, Blocks.vine, 2, 1);
        world.setBlock(i + 6, j + 2, k + 10, Blocks.vine, 2, 1);
        world.setBlock(i + 6, j + 2, k + 13, Blocks.vine, 1, 1);
        world.setBlock(i + 6, j + 3, k + 2, Blocks.vine, 8, 1);
        world.setBlock(i + 6, j + 3, k + 4, Blocks.vine, 8, 1);
        world.setBlock(i + 6, j + 3, k + 5, Blocks.vine, 8, 1);
        world.setBlock(i + 6, j + 3, k + 6, Blocks.vine, 8, 1);
        world.setBlock(i + 6, j + 3, k + 7, Blocks.vine, 2, 1);
        world.setBlock(i + 6, j + 3, k + 9, Blocks.vine, 2, 1);
        world.setBlock(i + 6, j + 3, k + 10, Blocks.vine, 2, 1);
        world.setBlock(i + 6, j + 3, k + 13, Blocks.vine, 3, 1);
        world.setBlock(i + 6, j + 3, k + 19, Blocks.vine, 4, 1);
        world.setBlock(i + 6, j + 4, k + 2, Blocks.vine, 8, 1);
        world.setBlock(i + 6, j + 4, k + 4, Blocks.vine, 8, 1);
        world.setBlock(i + 6, j + 4, k + 5, Blocks.vine, 8, 1);
        world.setBlock(i + 6, j + 4, k + 6, Blocks.vine, 8, 1);
        world.setBlock(i + 6, j + 4, k + 13, Blocks.vine, 3, 1);
        world.setBlock(i + 6, j + 4, k + 19, Blocks.vine, 4, 1);
        world.setBlock(i + 6, j + 5, k + 13, Blocks.vine, 3, 1);
        world.setBlock(i + 6, j + 5, k + 19, Blocks.vine, 4, 1);
        world.setBlock(i + 6, j + 6, k + 13, Blocks.vine, 2, 1);
        world.setBlock(i + 7, j + 1, k + 8, Blocks.vine, 8, 1);
        world.setBlock(i + 7, j + 1, k + 12, Blocks.vine, 8, 1);
        world.setBlock(i + 7, j + 1, k + 13, Blocks.vine, 1, 1);
        world.setBlock(i + 7, j + 1, k + 16, Blocks.brown_mushroom);
        world.setBlock(i + 7, j + 2, k + 8, Blocks.vine, 8, 1);
        world.setBlock(i + 7, j + 2, k + 12, Blocks.vine, 8, 1);
        world.setBlock(i + 7, j + 2, k + 13, Blocks.vine, 1, 1);
        world.setBlock(i + 7, j + 3, k + 8, Blocks.vine, 8, 1);
        world.setBlock(i + 7, j + 3, k + 12, Blocks.vine, 8, 1);
        world.setBlock(i + 7, j + 3, k + 13, Blocks.vine, 1, 1);
        world.setBlock(i + 7, j + 4, k + 13, Blocks.vine, 1, 1);
        world.setBlock(i + 7, j + 5, k + 13, Blocks.vine, 1, 1);
        world.setBlock(i + 7, j + 5, k + 19, Blocks.vine, 4, 1);
        world.setBlock(i + 8, j + 1, k + 7, Blocks.vine, 1, 1);
        world.setBlock(i + 8, j + 1, k + 11, Blocks.vine, 1, 1);
        world.setBlock(i + 8, j + 1, k + 13, Blocks.vine, 4, 1);
        world.setBlock(i + 8, j + 1, k + 19, Blocks.vine, 4, 1);
        world.setBlock(i + 8, j + 2, k + 1, Blocks.vine, 1, 1);
        world.setBlock(i + 8, j + 2, k + 7, Blocks.vine, 1, 1);
        world.setBlock(i + 8, j + 2, k + 11, Blocks.vine, 1, 1);
        world.setBlock(i + 8, j + 2, k + 13, Blocks.vine, 4, 1);
        world.setBlock(i + 8, j + 2, k + 15, Blocks.vine, 1, 1);
        world.setBlock(i + 8, j + 2, k + 19, Blocks.vine, 4, 1);
        world.setBlock(i + 8, j + 3, k + 1, Blocks.vine, 1, 1);
        world.setBlock(i + 8, j + 3, k + 4, Blocks.vine, 8, 1);
        world.setBlock(i + 8, j + 3, k + 7, Blocks.vine, 5, 1);
        world.setBlock(i + 8, j + 3, k + 11, Blocks.vine, 1, 1);
        world.setBlock(i + 8, j + 3, k + 13, Blocks.vine, 4, 1);
        world.setBlock(i + 8, j + 3, k + 15, Blocks.vine, 1, 1);
        world.setBlock(i + 8, j + 3, k + 17, Blocks.vine, 4, 1);
        world.setBlock(i + 8, j + 3, k + 19, Blocks.vine, 4, 1);
        world.setBlock(i + 8, j + 4, k + 1, Blocks.vine, 1, 1);
        world.setBlock(i + 8, j + 4, k + 7, Blocks.vine, 4, 1);
        world.setBlock(i + 8, j + 4, k + 15, Blocks.vine, 1, 1);
        world.setBlock(i + 8, j + 4, k + 17, Blocks.vine, 4, 1);
        world.setBlock(i + 8, j + 4, k + 19, Blocks.vine, 4, 1);
        world.setBlock(i + 8, j + 5, k + 19, Blocks.vine, 4, 1);
        world.setBlock(i + 9, j + 1, k + 3, Blocks.vine, 1, 1);
        world.setBlock(i + 9, j + 1, k + 7, Blocks.vine, 4, 1);
        world.setBlock(i + 9, j + 1, k + 12, Blocks.vine, 2, 1);
        world.setBlock(i + 9, j + 1, k + 16, Blocks.brown_mushroom);
        world.setBlock(i + 9, j + 2, k + 3, Blocks.vine, 1, 1);
        world.setBlock(i + 9, j + 2, k + 5, Blocks.vine, 4, 1);
        world.setBlock(i + 9, j + 2, k + 7, Blocks.vine, 4, 1);
        world.setBlock(i + 9, j + 2, k + 12, Blocks.vine, 2, 1);
        world.setBlock(i + 9, j + 2, k + 13, Blocks.vine, 1, 1);
        world.setBlock(i + 9, j + 3, k + 3, Blocks.vine, 1, 1);
        world.setBlock(i + 9, j + 3, k + 5, Blocks.vine, 4, 1);
        world.setBlock(i + 9, j + 3, k + 7, Blocks.vine, 4, 1);
        world.setBlock(i + 9, j + 3, k + 8, Blocks.vine, 2, 1);
        world.setBlock(i + 9, j + 3, k + 12, Blocks.vine, 2, 1);
        world.setBlock(i + 9, j + 3, k + 13, Blocks.vine, 1, 1);
        world.setBlock(i + 9, j + 3, k + 16, Blocks.vine, 2, 1);
        world.setBlock(i + 9, j + 3, k + 19, Blocks.vine, 4, 1);
        world.setBlock(i + 9, j + 4, k + 1, Blocks.vine, 1, 1);
        world.setBlock(i + 9, j + 4, k + 7, Blocks.vine, 4, 1);
        world.setBlock(i + 9, j + 4, k + 13, Blocks.vine, 1, 1);
        world.setBlock(i + 9, j + 4, k + 16, Blocks.vine, 2, 1);
        world.setBlock(i + 9, j + 4, k + 19, Blocks.vine, 4, 1);
        world.setBlock(i + 9, j + 5, k + 13, Blocks.vine, 1, 1);
        world.setBlock(i + 9, j + 5, k + 19, Blocks.vine, 4, 1);
        world.setBlock(i + 9, j + 6, k + 6, Blocks.vine, 4, 1);
        world.setBlock(i + 9, j + 6, k + 19, Blocks.vine, 4, 1);
        world.setBlock(i + 9, j + 7, k + 6, Blocks.vine, 4, 1);
        world.setBlock(i + 10, j + 1, k + 7, Blocks.vine, 4, 1);
        world.setBlock(i + 10, j + 1, k + 15, Blocks.red_mushroom);
        world.setBlock(i + 10, j + 2, k + 1, Blocks.vine, 1, 1);
        world.setBlock(i + 10, j + 2, k + 4, Blocks.vine, 2, 1);
        world.setBlock(i + 10, j + 2, k + 7, Blocks.vine, 4, 1);
        world.setBlock(i + 10, j + 3, k + 1, Blocks.vine, 1, 1);
        world.setBlock(i + 10, j + 3, k + 4, Blocks.vine, 2, 1);
        world.setBlock(i + 10, j + 3, k + 7, Blocks.vine, 4, 1);
        world.setBlock(i + 10, j + 3, k + 11, Blocks.vine, 1, 1);
        world.setBlock(i + 10, j + 3, k + 18, Blocks.vine, 4, 1);
        world.setBlock(i + 10, j + 4, k + 1, Blocks.vine, 1, 1);
        world.setBlock(i + 10, j + 4, k + 7, Blocks.vine, 4, 1);
        world.setBlock(i + 10, j + 4, k + 11, Blocks.vine, 1, 1);
        world.setBlock(i + 10, j + 4, k + 13, Blocks.vine, 1, 1);
        world.setBlock(i + 10, j + 4, k + 18, Blocks.vine, 4, 1);
        world.setBlock(i + 10, j + 4, k + 19, Blocks.vine, 4, 1);
        world.setBlock(i + 10, j + 5, k + 11, Blocks.vine, 1, 1);
        world.setBlock(i + 10, j + 5, k + 13, Blocks.vine, 1, 1);
        world.setBlock(i + 10, j + 5, k + 18, Blocks.vine, 4, 1);
        world.setBlock(i + 10, j + 5, k + 19, Blocks.vine, 4, 1);
        world.setBlock(i + 10, j + 6, k + 11, Blocks.vine, 1, 1);
        world.setBlock(i + 10, j + 6, k + 19, Blocks.vine, 4, 1);
        world.setBlock(i + 11, j + 1, k + 7, Blocks.vine, 4, 1);
        world.setBlock(i + 11, j + 1, k + 8, Blocks.vine, 8, 1);
        world.setBlock(i + 11, j + 2, k + 7, Blocks.vine, 4, 1);
        world.setBlock(i + 11, j + 2, k + 8, Blocks.vine, 8, 1);
        world.setBlock(i + 11, j + 3, k + 2, Blocks.vine, 1, 1);
        world.setBlock(i + 11, j + 3, k + 7, Blocks.vine, 4, 1);
        world.setBlock(i + 11, j + 3, k + 8, Blocks.vine, 8, 1);
        world.setBlock(i + 11, j + 3, k + 11, Blocks.vine, 1, 1);
        world.setBlock(i + 11, j + 4, k + 2, Blocks.vine, 1, 1);
        world.setBlock(i + 11, j + 4, k + 7, Blocks.vine, 4, 1);
        world.setBlock(i + 11, j + 4, k + 11, Blocks.vine, 1, 1);
        world.setBlock(i + 11, j + 4, k + 17, Blocks.vine, 2, 1);
        world.setBlock(i + 11, j + 5, k + 11, Blocks.vine, 1, 1);
        world.setBlock(i + 11, j + 5, k + 17, Blocks.vine, 2, 1);
        world.setBlock(i + 11, j + 6, k + 11, Blocks.vine, 1, 1);
        world.setBlock(i + 11, j + 6, k + 17, Blocks.vine, 2, 1);
        world.setBlock(i + 12, j + 1, k + 3, Blocks.vine, 2, 1);
        world.setBlock(i + 12, j + 1, k + 5, Blocks.vine, 2, 1);
        world.setBlock(i + 12, j + 1, k + 9, Blocks.vine, 4, 1);
        world.setBlock(i + 12, j + 1, k + 11, Blocks.vine, 1, 1);
        world.setBlock(i + 12, j + 1, k + 13, Blocks.vine, 4, 1);
        world.setBlock(i + 12, j + 2, k + 3, Blocks.vine, 2, 1);
        world.setBlock(i + 12, j + 2, k + 4, Blocks.vine, 2, 1);
        world.setBlock(i + 12, j + 2, k + 5, Blocks.vine, 2, 1);
        world.setBlock(i + 12, j + 2, k + 9, Blocks.vine, 4, 1);
        world.setBlock(i + 12, j + 2, k + 11, Blocks.vine, 1, 1);
        world.setBlock(i + 12, j + 2, k + 13, Blocks.vine, 4, 1);
        world.setBlock(i + 12, j + 3, k + 3, Blocks.vine, 2, 1);
        world.setBlock(i + 12, j + 3, k + 4, Blocks.vine, 2, 1);
        world.setBlock(i + 12, j + 3, k + 5, Blocks.vine, 2, 1);
        world.setBlock(i + 12, j + 3, k + 6, Blocks.vine, 2, 1);
        world.setBlock(i + 12, j + 3, k + 7, Blocks.vine, 1, 1);
        world.setBlock(i + 12, j + 3, k + 9, Blocks.vine, 4, 1);
        world.setBlock(i + 12, j + 3, k + 11, Blocks.vine, 1, 1);
        world.setBlock(i + 12, j + 3, k + 17, Blocks.vine, 4, 1);
        world.setBlock(i + 12, j + 4, k + 3, Blocks.vine, 2, 1);
        world.setBlock(i + 12, j + 4, k + 4, Blocks.vine, 2, 1);
        world.setBlock(i + 12, j + 4, k + 5, Blocks.vine, 2, 1);
        world.setBlock(i + 12, j + 4, k + 6, Blocks.vine, 2, 1);
        world.setBlock(i + 12, j + 4, k + 17, Blocks.vine, 4, 1);
        world.setBlock(i + 12, j + 5, k + 17, Blocks.vine, 4, 1);
        world.setBlock(i + 12, j + 6, k + 17, Blocks.vine, 4, 1);
        world.setBlock(i + 12, j + 7, k + 17, Blocks.vine, 4, 1);
        world.setBlock(i + 12, j + 8, k + 17, Blocks.vine, 4, 1);
        world.setBlock(i + 12, j + 9, k + 17, Blocks.vine, 4, 1);
        world.setBlock(i + 13, j + 1, k + 2, Blocks.vine, 8, 1);
        world.setBlock(i + 13, j + 1, k + 3, Blocks.vine, 8, 1);
        world.setBlock(i + 13, j + 1, k + 8, Blocks.vine, 2, 1);
        world.setBlock(i + 13, j + 1, k + 12, Blocks.vine, 2, 1);
        world.setBlock(i + 13, j + 1, k + 15, Blocks.red_mushroom);
        world.setBlock(i + 13, j + 2, k + 2, Blocks.vine, 8, 1);
        world.setBlock(i + 13, j + 2, k + 3, Blocks.vine, 8, 1);
        world.setBlock(i + 13, j + 2, k + 8, Blocks.vine, 2, 1);
        world.setBlock(i + 13, j + 2, k + 12, Blocks.vine, 2, 1);
        world.setBlock(i + 13, j + 3, k + 8, Blocks.vine, 2, 1);
        world.setBlock(i + 13, j + 3, k + 12, Blocks.vine, 2, 1);
        world.setBlock(i + 13, j + 3, k + 16, Blocks.vine, 2, 1);
        world.setBlock(i + 13, j + 4, k + 8, Blocks.vine, 8, 1);
        world.setBlock(i + 13, j + 4, k + 16, Blocks.vine, 2, 1);
        world.setBlock(i + 13, j + 5, k + 8, Blocks.vine, 8, 1);
        world.setBlock(i + 13, j + 5, k + 16, Blocks.vine, 2, 1);
        world.setBlock(i + 13, j + 6, k + 8, Blocks.vine, 8, 1);
        world.setBlock(i + 13, j + 6, k + 9, Blocks.vine, 8, 1);
        world.setBlock(i + 13, j + 6, k + 10, Blocks.vine, 8, 1);
        world.setBlock(i + 13, j + 6, k + 11, Blocks.vine, 8, 1);
        world.setBlock(i + 13, j + 6, k + 16, Blocks.vine, 2, 1);
        world.setBlock(i + 13, j + 7, k + 8, Blocks.vine, 8, 1);
        world.setBlock(i + 13, j + 7, k + 9, Blocks.vine, 8, 1);
        world.setBlock(i + 13, j + 7, k + 10, Blocks.vine, 8, 1);
        world.setBlock(i + 13, j + 7, k + 11, Blocks.vine, 8, 1);
        world.setBlock(i + 13, j + 7, k + 18, Blocks.vine, 4, 1);
        world.setBlock(i + 13, j + 8, k + 8, Blocks.vine, 8, 1);
        world.setBlock(i + 13, j + 8, k + 9, Blocks.vine, 8, 1);
        world.setBlock(i + 13, j + 8, k + 10, Blocks.vine, 8, 1);
        world.setBlock(i + 13, j + 8, k + 11, Blocks.vine, 8, 1);
        world.setBlock(i + 13, j + 8, k + 18, Blocks.vine, 4, 1);
        world.setBlock(i + 13, j + 9, k + 8, Blocks.vine, 8, 1);
        world.setBlock(i + 13, j + 9, k + 9, Blocks.vine, 8, 1);
        world.setBlock(i + 13, j + 9, k + 10, Blocks.vine, 8, 1);
        world.setBlock(i + 13, j + 9, k + 11, Blocks.vine, 8, 1);
        world.setBlock(i + 13, j + 9, k + 18, Blocks.vine, 4, 1);
        world.setBlock(i + 14, j + 0, k + 1, Blocks.vine, 1, 1);
        world.setBlock(i + 14, j + 1, k + 1, Blocks.vine, 1, 1);
        world.setBlock(i + 14, j + 2, k + 1, Blocks.vine, 1, 1);
        world.setBlock(i + 14, j + 3, k + 14, Blocks.vine, 2, 1);
        world.setBlock(i + 14, j + 4, k + 14, Blocks.vine, 2, 1);
        world.setBlock(i + 14, j + 5, k + 14, Blocks.vine, 2, 1);
        world.setBlock(i + 14, j + 6, k + 7, Blocks.vine, 1, 1);
        world.setBlock(i + 14, j + 6, k + 13, Blocks.vine, 2, 1);
        world.setBlock(i + 14, j + 6, k + 14, Blocks.vine, 2, 1);
        world.setBlock(i + 14, j + 7, k + 7, Blocks.vine, 1, 1);
        world.setBlock(i + 14, j + 7, k + 14, Blocks.vine, 2, 1);
        world.setBlock(i + 14, j + 7, k + 16, Blocks.vine, 4, 1);
        world.setBlock(i + 14, j + 7, k + 18, Blocks.vine, 4, 1);
        world.setBlock(i + 14, j + 8, k + 7, Blocks.vine, 1, 1);
        world.setBlock(i + 14, j + 8, k + 18, Blocks.vine, 4, 1);
        world.setBlock(i + 14, j + 9, k + 7, Blocks.vine, 1, 1);
        world.setBlock(i + 14, j + 9, k + 18, Blocks.vine, 4, 1);
        world.setBlock(i + 15, j + 1, k + 1, Blocks.vine, 1, 1);
        world.setBlock(i + 15, j + 2, k + 1, Blocks.vine, 1, 1);
        world.setBlock(i + 15, j + 3, k + 15, Blocks.vine, 2, 1);
        world.setBlock(i + 15, j + 4, k + 7, Blocks.vine, 1, 1);
        world.setBlock(i + 15, j + 4, k + 10, Blocks.vine, 8, 1);
        world.setBlock(i + 15, j + 4, k + 15, Blocks.vine, 2, 1);
        world.setBlock(i + 15, j + 5, k + 7, Blocks.vine, 1, 1);
        world.setBlock(i + 15, j + 5, k + 10, Blocks.vine, 8, 1);
        world.setBlock(i + 15, j + 5, k + 15, Blocks.vine, 2, 1);
        world.setBlock(i + 15, j + 6, k + 7, Blocks.vine, 1, 1);
        world.setBlock(i + 15, j + 6, k + 10, Blocks.vine, 8, 1);
        world.setBlock(i + 15, j + 6, k + 15, Blocks.vine, 2, 1);
        world.setBlock(i + 15, j + 7, k + 7, Blocks.vine, 1, 1);
        world.setBlock(i + 15, j + 7, k + 10, Blocks.vine, 8, 1);
        world.setBlock(i + 15, j + 7, k + 15, Blocks.vine, 2, 1);
        world.setBlock(i + 15, j + 7, k + 18, Blocks.vine, 4, 1);
        world.setBlock(i + 15, j + 8, k + 7, Blocks.vine, 1, 1);
        world.setBlock(i + 15, j + 8, k + 10, Blocks.vine, 8, 1);
        world.setBlock(i + 15, j + 8, k + 18, Blocks.vine, 4, 1);
        world.setBlock(i + 15, j + 9, k + 7, Blocks.vine, 1, 1);
        world.setBlock(i + 16, j + 0, k + 1, Blocks.vine, 1, 1);
        world.setBlock(i + 16, j + 1, k + 1, Blocks.vine, 1, 1);
        world.setBlock(i + 16, j + 2, k + 1, Blocks.vine, 1, 1);
        world.setBlock(i + 16, j + 5, k + 9, Blocks.vine, 1, 1);
        world.setBlock(i + 16, j + 5, k + 11, Blocks.vine, 4, 1);
        world.setBlock(i + 16, j + 6, k + 9, Blocks.vine, 1, 1);
        world.setBlock(i + 16, j + 6, k + 11, Blocks.vine, 4, 1);
        world.setBlock(i + 16, j + 6, k + 18, Blocks.vine, 4, 1);
        world.setBlock(i + 16, j + 7, k + 9, Blocks.vine, 1, 1);
        world.setBlock(i + 16, j + 7, k + 11, Blocks.vine, 4, 1);
        world.setBlock(i + 16, j + 7, k + 18, Blocks.vine, 4, 1);
        world.setBlock(i + 16, j + 8, k + 7, Blocks.vine, 1, 1);
        world.setBlock(i + 16, j + 8, k + 9, Blocks.vine, 1, 1);
        world.setBlock(i + 16, j + 8, k + 11, Blocks.vine, 4, 1);
        world.setBlock(i + 16, j + 8, k + 18, Blocks.vine, 4, 1);
        world.setBlock(i + 16, j + 9, k + 7, Blocks.vine, 1, 1);
        world.setBlock(i + 17, j + 0, k + 1, Blocks.vine, 1, 1);
        world.setBlock(i + 17, j + 1, k + 1, Blocks.vine, 1, 1);
        world.setBlock(i + 17, j + 2, k + 1, Blocks.vine, 1, 1);
        world.setBlock(i + 17, j + 3, k + 16, Blocks.vine, 2, 1);
        world.setBlock(i + 17, j + 4, k + 14, Blocks.vine, 2, 1);
        world.setBlock(i + 17, j + 4, k + 16, Blocks.vine, 2, 1);
        world.setBlock(i + 17, j + 5, k + 14, Blocks.vine, 2, 1);
        world.setBlock(i + 17, j + 5, k + 16, Blocks.vine, 2, 1);
        world.setBlock(i + 17, j + 6, k + 14, Blocks.vine, 2, 1);
        world.setBlock(i + 17, j + 6, k + 16, Blocks.vine, 2, 1);
        world.setBlock(i + 17, j + 6, k + 17, Blocks.vine, 2, 1);
        world.setBlock(i + 17, j + 7, k + 10, Blocks.vine, 2, 1);
        world.setBlock(i + 17, j + 7, k + 14, Blocks.vine, 2, 1);
        world.setBlock(i + 17, j + 7, k + 16, Blocks.vine, 2, 1);
        world.setBlock(i + 17, j + 7, k + 17, Blocks.vine, 2, 1);
        world.setBlock(i + 17, j + 8, k + 10, Blocks.vine, 2, 1);
        world.setBlock(i + 17, j + 8, k + 13, Blocks.vine, 2, 1);
        world.setBlock(i + 17, j + 8, k + 14, Blocks.vine, 2, 1);
        world.setBlock(i + 17, j + 8, k + 15, Blocks.vine, 2, 1);
        world.setBlock(i + 17, j + 8, k + 16, Blocks.vine, 2, 1);
        world.setBlock(i + 17, j + 8, k + 17, Blocks.vine, 2, 1);
        world.setBlock(i + 17, j + 9, k + 7, Blocks.vine, 1, 1);
        world.setBlock(i + 17, j + 9, k + 13, Blocks.vine, 2, 1);
        world.setBlock(i + 17, j + 9, k + 14, Blocks.vine, 2, 1);
        world.setBlock(i + 17, j + 9, k + 15, Blocks.vine, 2, 1);
        world.setBlock(i + 18, j + 0, k + 2, Blocks.vine, 1, 1);
        world.setBlock(i + 18, j + 1, k + 2, Blocks.vine, 1, 1);
        world.setBlock(i + 18, j + 2, k + 2, Blocks.vine, 1, 1);
        world.setBlock(i + 18, j + 8, k + 12, Blocks.vine, 2, 1);
        world.setBlock(i + 18, j + 9, k + 8, Blocks.vine, 2, 1);
        world.setBlock(i + 18, j + 9, k + 12, Blocks.vine, 2, 1);
        world.setBlock(i + 19, j + 0, k + 5, Blocks.vine, 2, 1);
        world.setBlock(i + 19, j + 0, k + 6, Blocks.vine, 2, 1);
        world.setBlock(i + 19, j + 1, k + 3, Blocks.vine, 2, 1);
        world.setBlock(i + 19, j + 1, k + 5, Blocks.vine, 2, 1);
        world.setBlock(i + 19, j + 1, k + 6, Blocks.vine, 2, 1);
        world.setBlock(i + 19, j + 2, k + 3, Blocks.vine, 2, 1);
        world.setBlock(i + 19, j + 2, k + 4, Blocks.vine, 2, 1);
        world.setBlock(i + 19, j + 2, k + 5, Blocks.vine, 2, 1);
        world.setBlock(i + 19, j + 2, k + 6, Blocks.vine, 2, 1);
        world.setBlock(i + 19, j + 5, k + 11, Blocks.vine, 2, 1);
        world.setBlock(i + 19, j + 6, k + 10, Blocks.vine, 2, 1);
        world.setBlock(i + 19, j + 6, k + 11, Blocks.vine, 2, 1);
        world.setBlock(i + 19, j + 7, k + 10, Blocks.vine, 2, 1);
        world.setBlock(i + 19, j + 7, k + 11, Blocks.vine, 2, 1);
        world.setBlock(i + 19, j + 8, k + 9, Blocks.vine, 2, 1);
        world.setBlock(i + 19, j + 8, k + 10, Blocks.vine, 2, 1);
        world.setBlock(i + 19, j + 8, k + 11, Blocks.vine, 2, 1);
        world.setBlock(i + 19, j + 9, k + 9, Blocks.vine, 2, 1);
        world.setBlock(i + 19, j + 9, k + 10, Blocks.vine, 2, 1);
        world.setBlock(i + 19, j + 9, k + 11, Blocks.vine, 2, 1);

        return true;
    }

}